Workbook

Sheet HAHA合集
A1: ID | B1: 品级 | C1: 丹药名称 | D1: 耐药性 | E1: 效果/丹毒 | F1: 主需求 | G1: 药力↓ | H1: 辅需求 | I1: 辅药力↓ | J1: 辅需求2 | K1: 辅药力2 | L1: 寒热 | M1: 药引药力 | N1: 丹药价值
A2: 5315 | B2: 4 | C2: 九转再造丹 | D2: 5 | E2: 资质+3/丹毒+2 | F2: 聚元 | G2: 252 | H2: 洗髓 | I2: 36 | L2: =IF(IFERROR(IF(AND(#REF!>0,#REF!<>""),VLOOKUP(#REF!,药材与丹炉!$B:$D,3,0),0),0)+IFERROR(IF(AND(#REF!>0,#REF!<>""),VLOOKUP(#REF!,药材与丹炉!$B:$D,3,0),0),0)+IFERROR(IF(AND(#REF!>0,#REF!<>""),VLOOKUP(#REF!,药材与丹炉!$B:$D,3,0),0),0)+IFERROR(IF(AND(#REF!>0,#REF!<>""),VLOOKUP(#REF!,药材与丹炉!$B:$D,3,0),0),0)>0,1,IF(IFERROR(IF(AND(#REF!>0,#REF!<>""),VLOOKUP(#REF!,药材与丹炉!$B:$D,3,0),0),0)+IFERROR(IF(AND(#REF!>0,#REF!<>""),VLOOKUP(#REF!,药材与丹炉!$B:$D,3,0),0),0)+IFERROR(IF(AND(#REF!>0,#REF!<>""),VLOOKUP(#REF!,药材与丹炉!$B:$D,3,0),0),0)+IFERROR(IF(AND(#REF!>0,#REF!<>""),VLOOKUP(#REF!,药材与丹炉!$B:$D,3,0),0),0)<0,2,0)) -> 0 | M2: 36 | N2: 31250
A3: 5321 | B3: 4 | C3: 蚀月强魂丹 | D3: 30 | E3: 下次战斗神识加10/丹毒+5 | F3: 振气 | G3: 36 | H3: 凝神 | I3: 36 | L3: =IF(IFERROR(IF(AND(#REF!>0,#REF!<>""),VLOOKUP(#REF!,药材与丹炉!$B:$D,3,0),0),0)+IFERROR(IF(AND(#REF!>0,#REF!<>""),VLOOKUP(#REF!,药材与丹炉!$B:$D,3,0),0),0)+IFERROR(IF(AND(#REF!>0,#REF!<>""),VLOOKUP(#REF!,药材与丹炉!$B:$D,3,0),0),0)+IFERROR(IF(AND(#REF!>0,#REF!<>""),VLOOKUP(#REF!,药材与丹炉!$B:$D,3,0),0),0)>0,1,IF(IFERROR(IF(AND(#REF!>0,#REF!<>""),VLOOKUP(#REF!,药材与丹炉!$B:$D,3,0),0),0)+IFERROR(IF(AND(#REF!>0,#REF!<>""),VLOOKUP(#REF!,药材与丹炉!$B:$D,3,0),0),0)+IFERROR(IF(AND(#REF!>0,#REF!<>""),VLOOKUP(#REF!,药材与丹炉!$B:$D,3,0),0),0)+IFERROR(IF(AND(#REF!>0,#REF!<>""),VLOOKUP(#REF!,药材与丹炉!$B:$D,3,0),0),0)<0,2,0)) -> 0 | M3: 36 | N3: 8000
A4: 5402 | B4: 5 | C4: 天尘丹 | D4: 100 | E4: 修为+118800，境界不足元婴期时服用，额外获得30丹毒。 | F4: 生息 | G4: 360 | H4: 炼气 | I4: 180 | L4: =IF(IFERROR(IF(AND(#REF!>0,#REF!<>""),VLOOKUP(#REF!,药材与丹炉!$B:$D,3,0),0),0)+IFERROR(IF(AND(#REF!>0,#REF!<>""),VLOOKUP(#REF!,药材与丹炉!$B:$D,3,0),0),0)+IFERROR(IF(AND(#REF!>0,#REF!<>""),VLOOKUP(#REF!,药材与丹炉!$B:$D,3,0),0),0)+IFERROR(IF(AND(#REF!>0,#REF!<>""),VLOOKUP(#REF!,药材与丹炉!$B:$D,3,0),0),0)>0,1,IF(IFERROR(IF(AND(#REF!>0,#REF!<>""),VLOOKUP(#REF!,药材与丹炉!$B:$D,3,0),0),0)+IFERROR(IF(AND(#REF!>0,#REF!<>""),VLOOKUP(#REF!,药材与丹炉!$B:$D,3,0),0),0)+IFERROR(IF(AND(#REF!>0,#REF!<>""),VLOOKUP(#REF!,药材与丹炉!$B:$D,3,0),0),0)+IFERROR(IF(AND(#REF!>0,#REF!<>""),VLOOKUP(#REF!,药材与丹炉!$B:$D,3,0),0),0)<0,2,0)) -> 0 | M4: 36 | N4: 118800
A5: 5404 | B5: 5 | C5: 长生丹 | D5: 5 | E5: 寿元+30 | F5: 聚元 | G5: 288 | H5: 益寿 | I5: 360 | L5: =IF(IFERROR(IF(AND(#REF!>0,#REF!<>""),VLOOKUP(#REF!,药材与丹炉!$B:$D,3,0),0),0)+IFERROR(IF(AND(#REF!>0,#REF!<>""),VLOOKUP(#REF!,药材与丹炉!$B:$D,3,0),0),0)+IFERROR(IF(AND(#REF!>0,#REF!<>""),VLOOKUP(#REF!,药材与丹炉!$B:$D,3,0),0),0)+IFERROR(IF(AND(#REF!>0,#REF!<>""),VLOOKUP(#REF!,药材与丹炉!$B:$D,3,0),0),0)>0,1,IF(IFERROR(IF(AND(#REF!>0,#REF!<>""),VLOOKUP(#REF!,药材与丹炉!$B:$D,3,0),0),0)+IFERROR(IF(AND(#REF!>0,#REF!<>""),VLOOKUP(#REF!,药材与丹炉!$B:$D,3,0),0),0)+IFERROR(IF(AND(#REF!>0,#REF!<>""),VLOOKUP(#REF!,药材与丹炉!$B:$D,3,0),0),0)+IFERROR(IF(AND(#REF!>0,#REF!<>""),VLOOKUP(#REF!,药材与丹炉!$B:$D,3,0),0),0)<0,2,0)) -> 0 | M5: 36 | N5: 100000
A6: 5405 | B6: 5 | C6: 厉魄丹 | D6: 2 | E6: 神识+4/丹毒+2 | F6: 聚元 | G6: 216 | H6: 养魂 | I6: 180 | L6: =IF(IFERROR(IF(AND(#REF!>0,#REF!<>""),VLOOKUP(#REF!,药材与丹炉!$B:$D,3,0),0),0)+IFERROR(IF(AND(#REF!>0,#REF!<>""),VLOOKUP(#REF!,药材与丹炉!$B:$D,3,0),0),0)+IFERROR(IF(AND(#REF!>0,#REF!<>""),VLOOKUP(#REF!,药材与丹炉!$B:$D,3,0),0),0)+IFERROR(IF(AND(#REF!>0,#REF!<>""),VLOOKUP(#REF!,药材与丹炉!$B:$D,3,0),0),0)>0,1,IF(IFERROR(IF(AND(#REF!>0,#REF!<>""),VLOOKUP(#REF!,药材与丹炉!$B:$D,3,0),0),0)+IFERROR(IF(AND(#REF!>0,#REF!<>""),VLOOKUP(#REF!,药材与丹炉!$B:$D,3,0),0),0)+IFERROR(IF(AND(#REF!>0,#REF!<>""),VLOOKUP(#REF!,药材与丹炉!$B:$D,3,0),0),0)+IFERROR(IF(AND(#REF!>0,#REF!<>""),VLOOKUP(#REF!,药材与丹炉!$B:$D,3,0),0),0)<0,2,0)) -> 0 | M6: 9 | N6: 57500
A7: 5406 | B7: 5 | C7: 朝元丹 | D7: 1 | E7: 在五气朝元阶段，每回合抽牌数+1/丹毒+6 | F7: 振气 | G7: 18 | H7: 凝液 | I7: 72 | J7: 聚灵 | K7: 36 | L7: =IF(IFERROR(IF(AND(#REF!>0,#REF!<>""),VLOOKUP(#REF!,药材与丹炉!$B:$D,3,0),0),0)+IFERROR(IF(AND(#REF!>0,#REF!<>""),VLOOKUP(#REF!,药材与丹炉!$B:$D,3,0),0),0)+IFERROR(IF(AND(#REF!>0,#REF!<>""),VLOOKUP(#REF!,药材与丹炉!$B:$D,3,0),0),0)+IFERROR(IF(AND(#REF!>0,#REF!<>""),VLOOKUP(#REF!,药材与丹炉!$B:$D,3,0),0),0)>0,1,IF(IFERROR(IF(AND(#REF!>0,#REF!<>""),VLOOKUP(#REF!,药材与丹炉!$B:$D,3,0),0),0)+IFERROR(IF(AND(#REF!>0,#REF!<>""),VLOOKUP(#REF!,药材与丹炉!$B:$D,3,0),0),0)+IFERROR(IF(AND(#REF!>0,#REF!<>""),VLOOKUP(#REF!,药材与丹炉!$B:$D,3,0),0),0)+IFERROR(IF(AND(#REF!>0,#REF!<>""),VLOOKUP(#REF!,药材与丹炉!$B:$D,3,0),0),0)<0,2,0)) -> 0 | M7: 9 | N7: 12500
A8: 5407 | B8: 5 | C8: 鐾金元丹 | D8: 10 | E8: 提升金之道悟道经验600点/丹毒+2 | F8: 聚元 | G8: 180 | H8: 强金 | I8: 540 | J8: 道蕴 | K8: 180 | L8: =IF(IFERROR(IF(AND(#REF!>0,#REF!<>""),VLOOKUP(#REF!,药材与丹炉!$B:$D,3,0),0),0)+IFERROR(IF(AND(#REF!>0,#REF!<>""),VLOOKUP(#REF!,药材与丹炉!$B:$D,3,0),0),0)+IFERROR(IF(AND(#REF!>0,#REF!<>""),VLOOKUP(#REF!,药材与丹炉!$B:$D,3,0),0),0)+IFERROR(IF(AND(#REF!>0,#REF!<>""),VLOOKUP(#REF!,药材与丹炉!$B:$D,3,0),0),0)>0,1,IF(IFERROR(IF(AND(#REF!>0,#REF!<>""),VLOOKUP(#REF!,药材与丹炉!$B:$D,3,0),0),0)+IFERROR(IF(AND(#REF!>0,#REF!<>""),VLOOKUP(#REF!,药材与丹炉!$B:$D,3,0),0),0)+IFERROR(IF(AND(#REF!>0,#REF!<>""),VLOOKUP(#REF!,药材与丹炉!$B:$D,3,0),0),0)+IFERROR(IF(AND(#REF!>0,#REF!<>""),VLOOKUP(#REF!,药材与丹炉!$B:$D,3,0),0),0)<0,2,0)) -> 0 | M8: 180 | N8: 180000
A9: 5408 | B9: 5 | C9: 森檀元丹 | D9: 10 | E9: 提升木之道悟道经验600点/丹毒+2 | F9: 聚元 | G9: 180 | H9: 强木 | I9: 540 | J9: 道蕴 | K9: 180 | L9: =IF(IFERROR(IF(AND(#REF!>0,#REF!<>""),VLOOKUP(#REF!,药材与丹炉!$B:$D,3,0),0),0)+IFERROR(IF(AND(#REF!>0,#REF!<>""),VLOOKUP(#REF!,药材与丹炉!$B:$D,3,0),0),0)+IFERROR(IF(AND(#REF!>0,#REF!<>""),VLOOKUP(#REF!,药材与丹炉!$B:$D,3,0),0),0)+IFERROR(IF(AND(#REF!>0,#REF!<>""),VLOOKUP(#REF!,药材与丹炉!$B:$D,3,0),0),0)>0,1,IF(IFERROR(IF(AND(#REF!>0,#REF!<>""),VLOOKUP(#REF!,药材与丹炉!$B:$D,3,0),0),0)+IFERROR(IF(AND(#REF!>0,#REF!<>""),VLOOKUP(#REF!,药材与丹炉!$B:$D,3,0),0),0)+IFERROR(IF(AND(#REF!>0,#REF!<>""),VLOOKUP(#REF!,药材与丹炉!$B:$D,3,0),0),0)+IFERROR(IF(AND(#REF!>0,#REF!<>""),VLOOKUP(#REF!,药材与丹炉!$B:$D,3,0),0),0)<0,2,0)) -> 0 | M9: 180 | N9: 180000
A10: 5409 | B10: 5 | C10: 浩淼元丹 | D10: 10 | E10: 提升水之道悟道经验600点/丹毒+2 | F10: 聚元 | G10: 180 | H10: 强水 | I10: 540 | J10: 道蕴 | K10: 180 | L10: =IF(IFERROR(IF(AND(#REF!>0,#REF!<>""),VLOOKUP(#REF!,药材与丹炉!$B:$D,3,0),0),0)+IFERROR(IF(AND(#REF!>0,#REF!<>""),VLOOKUP(#REF!,药材与丹炉!$B:$D,3,0),0),0)+IFERROR(IF(AND(#REF!>0,#REF!<>""),VLOOKUP(#REF!,药材与丹炉!$B:$D,3,0),0),0)+IFERROR(IF(AND(#REF!>0,#REF!<>""),VLOOKUP(#REF!,药材与丹炉!$B:$D,3,0),0),0)>0,1,IF(IFERROR(IF(AND(#REF!>0,#REF!<>""),VLOOKUP(#REF!,药材与丹炉!$B:$D,3,0),0),0)+IFERROR(IF(AND(#REF!>0,#REF!<>""),VLOOKUP(#REF!,药材与丹炉!$B:$D,3,0),0),0)+IFERROR(IF(AND(#REF!>0,#REF!<>""),VLOOKUP(#REF!,药材与丹炉!$B:$D,3,0),0),0)+IFERROR(IF(AND(#REF!>0,#REF!<>""),VLOOKUP(#REF!,药材与丹炉!$B:$D,3,0),0),0)<0,2,0)) -> 0 | M10: 180 | N10: 180000
A11: 5410 | B11: 5 | C11: 芒焰元丹 | D11: 10 | E11: 提升火之道悟道经验600点/丹毒+2 | F11: 聚元 | G11: 180 | H11: 强火 | I11: 540 | J11: 道蕴 | K11: 180 | L11: =IF(IFERROR(IF(AND(#REF!>0,#REF!<>""),VLOOKUP(#REF!,药材与丹炉!$B:$D,3,0),0),0)+IFERROR(IF(AND(#REF!>0,#REF!<>""),VLOOKUP(#REF!,药材与丹炉!$B:$D,3,0),0),0)+IFERROR(IF(AND(#REF!>0,#REF!<>""),VLOOKUP(#REF!,药材与丹炉!$B:$D,3,0),0),0)+IFERROR(IF(AND(#REF!>0,#REF!<>""),VLOOKUP(#REF!,药材与丹炉!$B:$D,3,0),0),0)>0,1,IF(IFERROR(IF(AND(#REF!>0,#REF!<>""),VLOOKUP(#REF!,药材与丹炉!$B:$D,3,0),0),0)+IFERROR(IF(AND(#REF!>0,#REF!<>""),VLOOKUP(#REF!,药材与丹炉!$B:$D,3,0),0),0)+IFERROR(IF(AND(#REF!>0,#REF!<>""),VLOOKUP(#REF!,药材与丹炉!$B:$D,3,0),0),0)+IFERROR(IF(AND(#REF!>0,#REF!<>""),VLOOKUP(#REF!,药材与丹炉!$B:$D,3,0),0),0)<0,2,0)) -> 0 | M11: 180 | N11: 180000
A12: 5411 | B12: 5 | C12: 无垠元丹 | D12: 10 | E12: 提升土之道悟道经验600点/丹毒+2 | F12: 聚元 | G12: 180 | H12: 强土 | I12: 540 | J12: 道蕴 | K12: 180 | L12: =IF(IFERROR(IF(AND(#REF!>0,#REF!<>""),VLOOKUP(#REF!,药材与丹炉!$B:$D,3,0),0),0)+IFERROR(IF(AND(#REF!>0,#REF!<>""),VLOOKUP(#REF!,药材与丹炉!$B:$D,3,0),0),0)+IFERROR(IF(AND(#REF!>0,#REF!<>""),VLOOKUP(#REF!,药材与丹炉!$B:$D,3,0),0),0)+IFERROR(IF(AND(#REF!>0,#REF!<>""),VLOOKUP(#REF!,药材与丹炉!$B:$D,3,0),0),0)>0,1,IF(IFERROR(IF(AND(#REF!>0,#REF!<>""),VLOOKUP(#REF!,药材与丹炉!$B:$D,3,0),0),0)+IFERROR(IF(AND(#REF!>0,#REF!<>""),VLOOKUP(#REF!,药材与丹炉!$B:$D,3,0),0),0)+IFERROR(IF(AND(#REF!>0,#REF!<>""),VLOOKUP(#REF!,药材与丹炉!$B:$D,3,0),0),0)+IFERROR(IF(AND(#REF!>0,#REF!<>""),VLOOKUP(#REF!,药材与丹炉!$B:$D,3,0),0),0)<0,2,0)) -> 0 | M12: 180 | N12: 180000
A13: 5412 | B13: 5 | C13: 天剑元丹 | D13: 10 | E13: 提升剑之道悟道经验600点/丹毒+2 | F13: 聚元 | G13: 180 | H13: 剑意 | I13: 540 | J13: 道蕴 | K13: 180 | L13: =IF(IFERROR(IF(AND(#REF!>0,#REF!<>""),VLOOKUP(#REF!,药材与丹炉!$B:$D,3,0),0),0)+IFERROR(IF(AND(#REF!>0,#REF!<>""),VLOOKUP(#REF!,药材与丹炉!$B:$D,3,0),0),0)+IFERROR(IF(AND(#REF!>0,#REF!<>""),VLOOKUP(#REF!,药材与丹炉!$B:$D,3,0),0),0)+IFERROR(IF(AND(#REF!>0,#REF!<>""),VLOOKUP(#REF!,药材与丹炉!$B:$D,3,0),0),0)>0,1,IF(IFERROR(IF(AND(#REF!>0,#REF!<>""),VLOOKUP(#REF!,药材与丹炉!$B:$D,3,0),0),0)+IFERROR(IF(AND(#REF!>0,#REF!<>""),VLOOKUP(#REF!,药材与丹炉!$B:$D,3,0),0),0)+IFERROR(IF(AND(#REF!>0,#REF!<>""),VLOOKUP(#REF!,药材与丹炉!$B:$D,3,0),0),0)+IFERROR(IF(AND(#REF!>0,#REF!<>""),VLOOKUP(#REF!,药材与丹炉!$B:$D,3,0),0),0)<0,2,0)) -> 0 | M13: 180 | N13: 180000
A14: 5413 | B14: 5 | C14: 炼魂元丹 | D14: 10 | E14: 提升神之道悟道经验600点/丹毒+2 | F14: 聚元 | G14: 180 | H14: 凝神 | I14: 540 | J14: 道蕴 | K14: 180 | L14: =IF(IFERROR(IF(AND(#REF!>0,#REF!<>""),VLOOKUP(#REF!,药材与丹炉!$B:$D,3,0),0),0)+IFERROR(IF(AND(#REF!>0,#REF!<>""),VLOOKUP(#REF!,药材与丹炉!$B:$D,3,0),0),0)+IFERROR(IF(AND(#REF!>0,#REF!<>""),VLOOKUP(#REF!,药材与丹炉!$B:$D,3,0),0),0)+IFERROR(IF(AND(#REF!>0,#REF!<>""),VLOOKUP(#REF!,药材与丹炉!$B:$D,3,0),0),0)>0,1,IF(IFERROR(IF(AND(#REF!>0,#REF!<>""),VLOOKUP(#REF!,药材与丹炉!$B:$D,3,0),0),0)+IFERROR(IF(AND(#REF!>0,#REF!<>""),VLOOKUP(#REF!,药材与丹炉!$B:$D,3,0),0),0)+IFERROR(IF(AND(#REF!>0,#REF!<>""),VLOOKUP(#REF!,药材与丹炉!$B:$D,3,0),0),0)+IFERROR(IF(AND(#REF!>0,#REF!<>""),VLOOKUP(#REF!,药材与丹炉!$B:$D,3,0),0),0)<0,2,0)) -> 0 | M14: 180 | N14: 180000
A15: 5414 | B15: 5 | C15: 道源丹 | D15: 3 | E15: 增加悟道点1点/丹毒+2 | F15: 聚元 | G15: 360 | H15: 开悟 | I15: 1260 | L15: =IF(IFERROR(IF(AND(#REF!>0,#REF!<>""),VLOOKUP(#REF!,药材与丹炉!$B:$D,3,0),0),0)+IFERROR(IF(AND(#REF!>0,#REF!<>""),VLOOKUP(#REF!,药材与丹炉!$B:$D,3,0),0),0)+IFERROR(IF(AND(#REF!>0,#REF!<>""),VLOOKUP(#REF!,药材与丹炉!$B:$D,3,0),0),0)+IFERROR(IF(AND(#REF!>0,#REF!<>""),VLOOKUP(#REF!,药材与丹炉!$B:$D,3,0),0),0)>0,1,IF(IFERROR(IF(AND(#REF!>0,#REF!<>""),VLOOKUP(#REF!,药材与丹炉!$B:$D,3,0),0),0)+IFERROR(IF(AND(#REF!>0,#REF!<>""),VLOOKUP(#REF!,药材与丹炉!$B:$D,3,0),0),0)+IFERROR(IF(AND(#REF!>0,#REF!<>""),VLOOKUP(#REF!,药材与丹炉!$B:$D,3,0),0),0)+IFERROR(IF(AND(#REF!>0,#REF!<>""),VLOOKUP(#REF!,药材与丹炉!$B:$D,3,0),0),0)<0,2,0)) -> 0 | M15: 180 | N15: 270000
A16: 5415 | B16: 5 | C16: 玉清昊元丹 | D16: 3 | E16: 悟性+4/丹毒+2 | F16: 聚元 | G16: 180 | H16: 开窍 | I16: 180 | J16: 调和 | K16: 180 | L16: =IF(IFERROR(IF(AND(#REF!>0,#REF!<>""),VLOOKUP(#REF!,药材与丹炉!$B:$D,3,0),0),0)+IFERROR(IF(AND(#REF!>0,#REF!<>""),VLOOKUP(#REF!,药材与丹炉!$B:$D,3,0),0),0)+IFERROR(IF(AND(#REF!>0,#REF!<>""),VLOOKUP(#REF!,药材与丹炉!$B:$D,3,0),0),0)+IFERROR(IF(AND(#REF!>0,#REF!<>""),VLOOKUP(#REF!,药材与丹炉!$B:$D,3,0),0),0)>0,1,IF(IFERROR(IF(AND(#REF!>0,#REF!<>""),VLOOKUP(#REF!,药材与丹炉!$B:$D,3,0),0),0)+IFERROR(IF(AND(#REF!>0,#REF!<>""),VLOOKUP(#REF!,药材与丹炉!$B:$D,3,0),0),0)+IFERROR(IF(AND(#REF!>0,#REF!<>""),VLOOKUP(#REF!,药材与丹炉!$B:$D,3,0),0),0)+IFERROR(IF(AND(#REF!>0,#REF!<>""),VLOOKUP(#REF!,药材与丹炉!$B:$D,3,0),0),0)<0,2,0)) -> 0 | M16: 36 | N16: 57500
A17: 5416 | B17: 5 | C17: 修髓丹 | D17: 1 | E17: 资质+9/丹毒+2 | F17: 聚元 | G17: 180 | H17: 洗髓 | I17: 180 | L17: =IF(IFERROR(IF(AND(#REF!>0,#REF!<>""),VLOOKUP(#REF!,药材与丹炉!$B:$D,3,0),0),0)+IFERROR(IF(AND(#REF!>0,#REF!<>""),VLOOKUP(#REF!,药材与丹炉!$B:$D,3,0),0),0)+IFERROR(IF(AND(#REF!>0,#REF!<>""),VLOOKUP(#REF!,药材与丹炉!$B:$D,3,0),0),0)+IFERROR(IF(AND(#REF!>0,#REF!<>""),VLOOKUP(#REF!,药材与丹炉!$B:$D,3,0),0),0)>0,1,IF(IFERROR(IF(AND(#REF!>0,#REF!<>""),VLOOKUP(#REF!,药材与丹炉!$B:$D,3,0),0),0)+IFERROR(IF(AND(#REF!>0,#REF!<>""),VLOOKUP(#REF!,药材与丹炉!$B:$D,3,0),0),0)+IFERROR(IF(AND(#REF!>0,#REF!<>""),VLOOKUP(#REF!,药材与丹炉!$B:$D,3,0),0),0)+IFERROR(IF(AND(#REF!>0,#REF!<>""),VLOOKUP(#REF!,药材与丹炉!$B:$D,3,0),0),0)<0,2,0)) -> 0 | M17: 180 | N17: 82000
A18: 5417 | B18: 5 | C18: 赤阳丹 | D18: 5 | E18: 生命值上限+20/丹毒+3 | F18: 聚元 | G18: 180 | H18: 煅体 | I18: 180 | L18: =IF(IFERROR(IF(AND(#REF!>0,#REF!<>""),VLOOKUP(#REF!,药材与丹炉!$B:$D,3,0),0),0)+IFERROR(IF(AND(#REF!>0,#REF!<>""),VLOOKUP(#REF!,药材与丹炉!$B:$D,3,0),0),0)+IFERROR(IF(AND(#REF!>0,#REF!<>""),VLOOKUP(#REF!,药材与丹炉!$B:$D,3,0),0),0)+IFERROR(IF(AND(#REF!>0,#REF!<>""),VLOOKUP(#REF!,药材与丹炉!$B:$D,3,0),0),0)>0,1,IF(IFERROR(IF(AND(#REF!>0,#REF!<>""),VLOOKUP(#REF!,药材与丹炉!$B:$D,3,0),0),0)+IFERROR(IF(AND(#REF!>0,#REF!<>""),VLOOKUP(#REF!,药材与丹炉!$B:$D,3,0),0),0)+IFERROR(IF(AND(#REF!>0,#REF!<>""),VLOOKUP(#REF!,药材与丹炉!$B:$D,3,0),0),0)+IFERROR(IF(AND(#REF!>0,#REF!<>""),VLOOKUP(#REF!,药材与丹炉!$B:$D,3,0),0),0)<0,2,0)) -> 0 | M18: 180 | N18: 82000
A19: 5418 | B19: 5 | C19: 青灵丹 | D19: 2 | E19: 遁速+9/丹毒+2 | F19: 聚元 | G19: 108 | H19: 神行 | I19: 72 | L19: =IF(IFERROR(IF(AND(#REF!>0,#REF!<>""),VLOOKUP(#REF!,药材与丹炉!$B:$D,3,0),0),0)+IFERROR(IF(AND(#REF!>0,#REF!<>""),VLOOKUP(#REF!,药材与丹炉!$B:$D,3,0),0),0)+IFERROR(IF(AND(#REF!>0,#REF!<>""),VLOOKUP(#REF!,药材与丹炉!$B:$D,3,0),0),0)+IFERROR(IF(AND(#REF!>0,#REF!<>""),VLOOKUP(#REF!,药材与丹炉!$B:$D,3,0),0),0)>0,1,IF(IFERROR(IF(AND(#REF!>0,#REF!<>""),VLOOKUP(#REF!,药材与丹炉!$B:$D,3,0),0),0)+IFERROR(IF(AND(#REF!>0,#REF!<>""),VLOOKUP(#REF!,药材与丹炉!$B:$D,3,0),0),0)+IFERROR(IF(AND(#REF!>0,#REF!<>""),VLOOKUP(#REF!,药材与丹炉!$B:$D,3,0),0),0)+IFERROR(IF(AND(#REF!>0,#REF!<>""),VLOOKUP(#REF!,药材与丹炉!$B:$D,3,0),0),0)<0,2,0)) -> 0 | M19: 36 | N19: 26250
A20: 5419 | B20: 5 | C20: 少阴清灵丹 | D20: 50 | E20: 心境+9 | F20: 聚元 | G20: 108 | H20: 清心 | I20: 72 | L20: =IF(IFERROR(IF(AND(#REF!>0,#REF!<>""),VLOOKUP(#REF!,药材与丹炉!$B:$D,3,0),0),0)+IFERROR(IF(AND(#REF!>0,#REF!<>""),VLOOKUP(#REF!,药材与丹炉!$B:$D,3,0),0),0)+IFERROR(IF(AND(#REF!>0,#REF!<>""),VLOOKUP(#REF!,药材与丹炉!$B:$D,3,0),0),0)+IFERROR(IF(AND(#REF!>0,#REF!<>""),VLOOKUP(#REF!,药材与丹炉!$B:$D,3,0),0),0)>0,1,IF(IFERROR(IF(AND(#REF!>0,#REF!<>""),VLOOKUP(#REF!,药材与丹炉!$B:$D,3,0),0),0)+IFERROR(IF(AND(#REF!>0,#REF!<>""),VLOOKUP(#REF!,药材与丹炉!$B:$D,3,0),0),0)+IFERROR(IF(AND(#REF!>0,#REF!<>""),VLOOKUP(#REF!,药材与丹炉!$B:$D,3,0),0),0)+IFERROR(IF(AND(#REF!>0,#REF!<>""),VLOOKUP(#REF!,药材与丹炉!$B:$D,3,0),0),0)<0,2,0)) -> 0 | M20: 36 | N20: 26250
A21: 5420 | B21: 5 | C21: 太乙降尘丹 | D21: 10 | E21: 丹毒-30 | F21: 净血 | G21: 108 | H21: 解毒 | I21: 72 | L21: =IF(IFERROR(IF(AND(#REF!>0,#REF!<>""),VLOOKUP(#REF!,药材与丹炉!$B:$D,3,0),0),0)+IFERROR(IF(AND(#REF!>0,#REF!<>""),VLOOKUP(#REF!,药材与丹炉!$B:$D,3,0),0),0)+IFERROR(IF(AND(#REF!>0,#REF!<>""),VLOOKUP(#REF!,药材与丹炉!$B:$D,3,0),0),0)+IFERROR(IF(AND(#REF!>0,#REF!<>""),VLOOKUP(#REF!,药材与丹炉!$B:$D,3,0),0),0)>0,1,IF(IFERROR(IF(AND(#REF!>0,#REF!<>""),VLOOKUP(#REF!,药材与丹炉!$B:$D,3,0),0),0)+IFERROR(IF(AND(#REF!>0,#REF!<>""),VLOOKUP(#REF!,药材与丹炉!$B:$D,3,0),0),0)+IFERROR(IF(AND(#REF!>0,#REF!<>""),VLOOKUP(#REF!,药材与丹炉!$B:$D,3,0),0),0)+IFERROR(IF(AND(#REF!>0,#REF!<>""),VLOOKUP(#REF!,药材与丹炉!$B:$D,3,0),0),0)<0,2,0)) -> 0 | M21: 36 | N21: 26250
A22: 5501 | B22: 5 | C22: 九转灵蛇丹 | D22: 100 | E22: 恢复全部生命值/丹毒+1 | F22: 活血 | G22: 9 | H22: 固元 | I22: 9 | J22: 培元 | K22: 9 | L22: =IF(IFERROR(IF(AND(#REF!>0,#REF!<>""),VLOOKUP(#REF!,药材与丹炉!$B:$D,3,0),0),0)+IFERROR(IF(AND(#REF!>0,#REF!<>""),VLOOKUP(#REF!,药材与丹炉!$B:$D,3,0),0),0)+IFERROR(IF(AND(#REF!>0,#REF!<>""),VLOOKUP(#REF!,药材与丹炉!$B:$D,3,0),0),0)+IFERROR(IF(AND(#REF!>0,#REF!<>""),VLOOKUP(#REF!,药材与丹炉!$B:$D,3,0),0),0)>0,1,IF(IFERROR(IF(AND(#REF!>0,#REF!<>""),VLOOKUP(#REF!,药材与丹炉!$B:$D,3,0),0),0)+IFERROR(IF(AND(#REF!>0,#REF!<>""),VLOOKUP(#REF!,药材与丹炉!$B:$D,3,0),0),0)+IFERROR(IF(AND(#REF!>0,#REF!<>""),VLOOKUP(#REF!,药材与丹炉!$B:$D,3,0),0),0)+IFERROR(IF(AND(#REF!>0,#REF!<>""),VLOOKUP(#REF!,药材与丹炉!$B:$D,3,0),0),0)<0,2,0)) -> 0 | M22: 9 | N22: 3500
A23: 5502 | B23: 6 | C23: 天元神丹 | D23: 100 | E23: 修为+594000，境界不足化神期时服用，额外获得30丹毒。 | F23: 生息 | G23: 81 | H23: 炼气 | I23: 2160 | L23: =IF(IFERROR(IF(AND(#REF!>0,#REF!<>""),VLOOKUP(#REF!,药材与丹炉!$B:$D,3,0),0),0)+IFERROR(IF(AND(#REF!>0,#REF!<>""),VLOOKUP(#REF!,药材与丹炉!$B:$D,3,0),0),0)+IFERROR(IF(AND(#REF!>0,#REF!<>""),VLOOKUP(#REF!,药材与丹炉!$B:$D,3,0),0),0)+IFERROR(IF(AND(#REF!>0,#REF!<>""),VLOOKUP(#REF!,药材与丹炉!$B:$D,3,0),0),0)>0,1,IF(IFERROR(IF(AND(#REF!>0,#REF!<>""),VLOOKUP(#REF!,药材与丹炉!$B:$D,3,0),0),0)+IFERROR(IF(AND(#REF!>0,#REF!<>""),VLOOKUP(#REF!,药材与丹炉!$B:$D,3,0),0),0)+IFERROR(IF(AND(#REF!>0,#REF!<>""),VLOOKUP(#REF!,药材与丹炉!$B:$D,3,0),0),0)+IFERROR(IF(AND(#REF!>0,#REF!<>""),VLOOKUP(#REF!,药材与丹炉!$B:$D,3,0),0),0)<0,2,0)) -> 0 | M23: 36 | N23: 594000
A24: 5512 | B24: 6 | C24: 天道源丹 | D24: 1 | E24: 增加悟道点3点/丹毒+2 | F24: 聚元 | G24: 2160 | H24: 开悟 | I24: 7560 | L24: =IF(IFERROR(IF(AND(#REF!>0,#REF!<>""),VLOOKUP(#REF!,药材与丹炉!$B:$D,3,0),0),0)+IFERROR(IF(AND(#REF!>0,#REF!<>""),VLOOKUP(#REF!,药材与丹炉!$B:$D,3,0),0),0)+IFERROR(IF(AND(#REF!>0,#REF!<>""),VLOOKUP(#REF!,药材与丹炉!$B:$D,3,0),0),0)+IFERROR(IF(AND(#REF!>0,#REF!<>""),VLOOKUP(#REF!,药材与丹炉!$B:$D,3,0),0),0)>0,1,IF(IFERROR(IF(AND(#REF!>0,#REF!<>""),VLOOKUP(#REF!,药材与丹炉!$B:$D,3,0),0),0)+IFERROR(IF(AND(#REF!>0,#REF!<>""),VLOOKUP(#REF!,药材与丹炉!$B:$D,3,0),0),0)+IFERROR(IF(AND(#REF!>0,#REF!<>""),VLOOKUP(#REF!,药材与丹炉!$B:$D,3,0),0),0)+IFERROR(IF(AND(#REF!>0,#REF!<>""),VLOOKUP(#REF!,药材与丹炉!$B:$D,3,0),0),0)<0,2,0)) -> 0 | M24: 1080 | N24: 1782000
A25: 5517 | B25: 6 | C25: 六阳长生丹 | D25: 5 | E25: 寿元+50 | F25: 聚元 | G25: 180 | H25: 益寿 | I25: 720 | L25: =IF(IFERROR(IF(AND(#REF!>0,#REF!<>""),VLOOKUP(#REF!,药材与丹炉!$B:$D,3,0),0),0)+IFERROR(IF(AND(#REF!>0,#REF!<>""),VLOOKUP(#REF!,药材与丹炉!$B:$D,3,0),0),0)+IFERROR(IF(AND(#REF!>0,#REF!<>""),VLOOKUP(#REF!,药材与丹炉!$B:$D,3,0),0),0)+IFERROR(IF(AND(#REF!>0,#REF!<>""),VLOOKUP(#REF!,药材与丹炉!$B:$D,3,0),0),0)>0,1,IF(IFERROR(IF(AND(#REF!>0,#REF!<>""),VLOOKUP(#REF!,药材与丹炉!$B:$D,3,0),0),0)+IFERROR(IF(AND(#REF!>0,#REF!<>""),VLOOKUP(#REF!,药材与丹炉!$B:$D,3,0),0),0)+IFERROR(IF(AND(#REF!>0,#REF!<>""),VLOOKUP(#REF!,药材与丹炉!$B:$D,3,0),0),0)+IFERROR(IF(AND(#REF!>0,#REF!<>""),VLOOKUP(#REF!,药材与丹炉!$B:$D,3,0),0),0)<0,2,0)) -> 0 | M25: 180 | N25: 220000

Sheet 记事本
B1: 默认适应X100%
B2: 部分数据源 | D2: 版本 | F2: 一仙道人 | I2: 属性 | J2: 一品 | K2: 二品 | L2: 三品 | M2: 四品 | N2: 五品 | O2: 六品 | Q2: 竹山丹圣-整合
B3: 丹普传承 | D3: 1.0 | F3: 武陵城 | G3: 44223 | I3: 心境 | J3: 冰心丹 | K3: 明心丹 | L3: 幻心玄丹 | M3: 鬼面炼心丹 | N3: 少阴清灵丹 | O3: 天命炼心丹
B4: 炼器传承 | D4: 2.0 | F4: 逸风城 | G4: 44267 | I4: 寿元 | K4: 续命丹 | L4: 延寿丹 | M4: 青冥丹 | N4: 长生丹 | O4: 六阳长生丹
B5: 流派传承 | D5: 2.0 | F5: 云汐城 | G5: 44372 | I5: 神识 | J5: 《23年1月18日》 =V1.7= 仙录传承更新 | L5: 养魂丹 | M5: 灵魂丹 | N5: 厉魂丹 | O5: 三阳锻魄丹
B6: 功法神通 | D6: 2.0 | F6: 天星城 | G6: 44421 | I6: 资质 | L6: 草还丹 | M6: 九转再造丹 | N6: 修髓丹 | O6: 太乙炼髓丹
B7: 复杂任务 | D7: 2.0 | F7: 广陵城 | G7: 44513 | I7: 遁速 | L7: 御风丹 | M7: 神行丹 | N7: 青灵丹 | O7: 太乙碧莹丹
B8: 境界突破 | D8: 2.0 | F8: 跑`商 | I8: 悟性 | L8: 启灵丹 | M8: 玄元丹 | N8: 玉清昊元丹 | O8: 太上玄门丹
B9: 年历游记 | D9: 2.0 | F9: 炼丹 | I9: 气血 | L9: 锻体丹 | M9: 金刚铁骨丹 | N9: 赤阳丹 | O9: 天命血凝丹
B10: 灵石笔记 | D10: 2.0 | F10: 炼器 | I10: 悟道 | N10: 道源丹 | O10: 天道源丹
B11: 桃花笔记 | D11: 1.3 | F11: 挖矿 | I11: 灵根 | K11: 金元丹 | L11: 水元丹 | M11: 木元丹 | N11: 火元丹 | O11: 土元丹
B13: 证道长生
B14: 相较于V1.6 更新了：炼丹模拟器->丹普传承，炼器表->炼器传承，，渡劫，功法神通检查，字体界面调整，流派->流派传承 修正了：炼器-天阳剑效果，练气期小境界提升血量调整，年历大量更新，化神领域效果 添加了：境界晋升修为需求，星官，龙宫，岫络谷，九州游记，灵石笔记，桃花笔记 删除了：流派评分，之前是看名字填的【狗头保命】，洞府，炼丹赚钱，灵石 额外的： 1.快捷键CTRL+F查找表内容 2.任何道友都可随意转载修改和使用，但不得用于商业目的 3.等待1.8的升级更新，计划年历，化神和渡劫整完，灵石攻略点名方向不做具体操作，合并表白攻略，剑灵剧情，合并龙宫与龙族剧情 4.攻略多来自各方道友，我主要制作页面，填充更新数据。同步数据于觅长生1.0.009 2023/1/18，如果版本更新或者表格错误，数据不对了可以来QQ频道传音符找我ID：竹山丹圣

Sheet 丹普传承
A1: ID | B1: 品级 | C1: 丹药名称 | D1: 耐药性 | E1: 效果/丹毒 | F1: 总主药需求 | G1: 主需求 | H1: 药力↓ | I1: 主药↓ | J1: 数量 | K1: 主需求2 | L1: 药力2 | M1: 主药2↓ | N1: 数量2 | O1: 总辅需求 | P1: 辅需求 | Q1: 辅药力↓ | R1: 辅药↓ | S1: 数量3 | T1: 辅需求2 | U1: 辅药力2 | V1: 辅药2↓ | W1: 数量4 | X1: 寒热 | Y1: 药引药力 | Z1: 药引↓ | AA1: 数量5 | AB1: 丹炉↓ | AC1: 丹炉耐久消耗 | AD1: 药材总数 | AE1: 炼丹理论消耗灵石 | AF1: 丹药价值 | AG1: 价值差 | AH1: 价格 | AI1: 价格差 | AJ1: 药引容量 | AK1: 是否出错 | AL1: 价格倍率→ | AM1: 2 | AN1: 控火悟道→ | AO1: 否
A2: 5001 | B2: 1 | C2: 化淤丹 | D2: 999 | E2: 生命值+20/丹毒+1 | F2: 1 | G2: 活血 | H2: 1 | I2: 天青花 | J2: =IFERROR(CEILING($H2/VLOOKUP($I2,药材与丹炉!$B:$H,COLUMN(药材与丹炉!$H2)-1,0),1),"") -> 1 | K2: 活血 | L2: =IFERROR(IF($F2-$H2=0,"",$F2-$H2),"") | N2: =IFERROR(CEILING($L2/VLOOKUP($M2,药材与丹炉!$B:$H,COLUMN(药材与丹炉!$H2)-1,0),1),"") | O2: 1 | P2: 培元 | Q2: 1 | R2: 流莹草 | S2: =IFERROR(CEILING($Q2/VLOOKUP($R2,药材与丹炉!$B:$H,COLUMN(药材与丹炉!$H2)-1,0),1),"") -> 1 | T2: =P2 -> 培元 | U2: =IFERROR(IF($O2-$Q2=0,"",$O2-$Q2),"") | W2: =IFERROR(CEILING($U2/VLOOKUP($V2,药材与丹炉!$B:$H,COLUMN(药材与丹炉!$H2)-1,0),1),"") | X2: =IF(IFERROR(IF(AND($J2>0,$J2<>""),VLOOKUP($I2,药材与丹炉!$B:$D,3,0),0),0)+IFERROR(IF(AND($N2>0,$N2<>""),VLOOKUP($M2,药材与丹炉!$B:$D,3,0),0),0)+IFERROR(IF(AND($S2>0,$S2<>""),VLOOKUP($R2,药材与丹炉!$B:$D,3,0),0),0)+IFERROR(IF(AND($W2>0,$W2<>""),VLOOKUP($V2,药材与丹炉!$B:$D,3,0),0),0)>0,1,IF(IFERROR(IF(AND($J2>0,$J2<>""),VLOOKUP($I2,药材与丹炉!$B:$D,3,0),0),0)+IFERROR(IF(AND($N2>0,$N2<>""),VLOOKUP($M2,药材与丹炉!$B:$D,3,0),0),0)+IFERROR(IF(AND($S2>0,$S2<>""),VLOOKUP($R2,药材与丹炉!$B:$D,3,0),0),0)+IFERROR(IF(AND($W2>0,$W2<>""),VLOOKUP($V2,药材与丹炉!$B:$D,3,0),0),0)<0,2,0)) -> 1 | Y2: 1 | Z2: 银月花 | AA2: =IFERROR($Y2/VLOOKUP($Z2,药材与丹炉!$B:$H,COLUMN(药材与丹炉!$H2)-1,0),"") -> 1 | AB2: 普通丹炉 | AC2: =IFERROR(IF($B2-VLOOKUP($AB2,药材与丹炉!$N:$P,2,0)<0,IF($AO$1="是",0,1),IF($B2-VLOOKUP($AB2,药材与丹炉!$N:$P,2,0)=0,2,IF($B2-VLOOKUP($AB2,药材与丹炉!$N:$P,2,0)=1,40,IF($B2-VLOOKUP($AB2,药材与丹炉!$N:$P,2,0)=2,80,"爆炸")))),"") -> 2 | AD2: =IFERROR($J2+IFERROR(IF($N2="",0,$N2),0)+IFERROR(IF($S2="",0,$S2),0)+IFERROR(IF($W2="",0,$W2),0)+IFERROR(IF($AA2="",0,$AA2),0),"") -> 3 | AE2: =IFERROR($J2*VLOOKUP($I2,药材与丹炉!$B:$K,10,0),0)+IFERROR($N2*VLOOKUP($M2,药材与丹炉!$B:$K,10,0),0)+IFERROR($S2*VLOOKUP($R2,药材与丹炉!$B:$K,10,0),0)+IFERROR($W2*VLOOKUP($V2,药材与丹炉!$B:$K,10,0),0)+IFERROR($AA2*VLOOKUP($Z2,药材与丹炉!$B:$K,10,0),0)+IFERROR($AC2*VLOOKUP($AB2,药材与丹炉!$N:$P,3,0)/100,0) -> 39 | AF2: 68 | AG2: =$AF2-$AE2 -> 29 | AH2: =$AF2*$AM$1*$AM$21 -> 136 | AI2: =$AH2-$AE2 -> 97 | AJ2: =IFERROR(IF($Y2/VLOOKUP($Y2,药材与丹炉!$T:$U,2,0)<=(VLOOKUP($AB2,药材与丹炉!$N:$O,2,0)+8)-($J2+IFERROR(IF($N2="",0,$N2),0)+IFERROR(IF($S2="",0,$S2),0)+IFERROR(IF($W2="",0,$W2),0)),1,2),1) -> 1 | AK2: =OR(NOT(IFERROR(OR($L2="",AND($L2<>"",$L2>0,VLOOKUP($AB2,药材与丹炉!$N:$O,2,0)=6)),0)),AND($L2<>"",$L2>0,OR(VLOOKUP($AB2,药材与丹炉!$N:$Q,4,0)-2<$N2,$N2="")),AND($U2<>"",$U2>0,OR(VLOOKUP($AB2,药材与丹炉!$N:$Q,4,0)-3<$W2,$W2="")),NOT(OR(AND($Q2<>"",$S2<>"",VLOOKUP($AB2,药材与丹炉!$N:$Q,4,0)-3>=$S2),$P2="")),NOT(OR(AND($H2<>"",$J2<>"",VLOOKUP($AB2,药材与丹炉!$N:$Q,4,0)-1>=$J2),$G2="")),NOT(OR($U2="",AND($U2<>"",$U2>0))),NOT(OR($Y2="",IF($Z2<>"",IFERROR(IF(VLOOKUP($Z2,药材与丹炉!$B:$D,3,0)=-1,$X2=1,IF(VLOOKUP($Z2,药材与丹炉!$B:$D,3,0)=1,$X2=2,$X2=0)),0),0))),$AC2="爆炸",(VLOOKUP($AB2,药材与丹炉!$N:$O,2,0)+8)<$AD2) -> FALSE | AL2: 控火悟道涵义： | AM2: 为"是"表示领悟了丹道融汇贯通中的控火，在计算炼丹消耗灵石价时减少丹炉所带的价格消耗；为"否"则正常计算丹炉损耗
A3: 5002 | B3: 1 | C3: 洗髓丹 | D3: 100 | E3: 修为+180 | F3: 15 | G3: 生息 | H3: 15 | I3: 何首乌 | J3: =IFERROR(CEILING($H3/VLOOKUP($I3,药材与丹炉!$B:$H,COLUMN(药材与丹炉!$H3)-1,0),1),"") -> 5 | K3: 生息 | L3: =IFERROR(IF($F3-$H3=0,"",$F3-$H3),"") | N3: =IFERROR(CEILING($L3/VLOOKUP($M3,药材与丹炉!$B:$H,COLUMN(药材与丹炉!$H3)-1,0),1),"") | S3: =IFERROR(CEILING($Q3/VLOOKUP($R3,药材与丹炉!$B:$H,COLUMN(药材与丹炉!$H3)-1,0),1),"") | U3: =IFERROR(IF($O3-$Q3=0,"",$O3-$Q3),"") | W3: =IFERROR(CEILING($U3/VLOOKUP($V3,药材与丹炉!$B:$H,COLUMN(药材与丹炉!$H3)-1,0),1),"") | X3: =IF(IFERROR(IF(AND($J3>0,$J3<>""),VLOOKUP($I3,药材与丹炉!$B:$D,3,0),0),0)+IFERROR(IF(AND($N3>0,$N3<>""),VLOOKUP($M3,药材与丹炉!$B:$D,3,0),0),0)+IFERROR(IF(AND($S3>0,$S3<>""),VLOOKUP($R3,药材与丹炉!$B:$D,3,0),0),0)+IFERROR(IF(AND($W3>0,$W3<>""),VLOOKUP($V3,药材与丹炉!$B:$D,3,0),0),0)>0,1,IF(IFERROR(IF(AND($J3>0,$J3<>""),VLOOKUP($I3,药材与丹炉!$B:$D,3,0),0),0)+IFERROR(IF(AND($N3>0,$N3<>""),VLOOKUP($M3,药材与丹炉!$B:$D,3,0),0),0)+IFERROR(IF(AND($S3>0,$S3<>""),VLOOKUP($R3,药材与丹炉!$B:$D,3,0),0),0)+IFERROR(IF(AND($W3>0,$W3<>""),VLOOKUP($V3,药材与丹炉!$B:$D,3,0),0),0)<0,2,0)) -> 1 | Y3: 1 | Z3: 宁心草 | AA3: =IFERROR($Y3/VLOOKUP($Z3,药材与丹炉!$B:$H,COLUMN(药材与丹炉!$H3)-1,0),"") -> 1 | AB3: 普通丹炉 | AC3: =IFERROR(IF($B3-VLOOKUP($AB3,药材与丹炉!$N:$P,2,0)<0,IF($AO$1="是",0,1),IF($B3-VLOOKUP($AB3,药材与丹炉!$N:$P,2,0)=0,2,IF($B3-VLOOKUP($AB3,药材与丹炉!$N:$P,2,0)=1,40,IF($B3-VLOOKUP($AB3,药材与丹炉!$N:$P,2,0)=2,80,"爆炸")))),"") -> 2 | AD3: =IFERROR($J3+IFERROR(IF($N3="",0,$N3),0)+IFERROR(IF($S3="",0,$S3),0)+IFERROR(IF($W3="",0,$W3),0)+IFERROR(IF($AA3="",0,$AA3),0),"") -> 6 | AE3: =IFERROR($J3*VLOOKUP($I3,药材与丹炉!$B:$K,10,0),0)+IFERROR($N3*VLOOKUP($M3,药材与丹炉!$B:$K,10,0),0)+IFERROR($S3*VLOOKUP($R3,药材与丹炉!$B:$K,10,0),0)+IFERROR($W3*VLOOKUP($V3,药材与丹炉!$B:$K,10,0),0)+IFERROR($AA3*VLOOKUP($Z3,药材与丹炉!$B:$K,10,0),0)+IFERROR($AC3*VLOOKUP($AB3,药材与丹炉!$N:$P,3,0)/100,0) -> 201 | AF3: 225 | AG3: =$AF3-$AE3 -> 24 | AH3: =$AF3*$AM$1*$AM$21 -> 450 | AI3: =$AH3-$AE3 -> 249 | AJ3: =IFERROR(IF($Y3/VLOOKUP($Y3,药材与丹炉!$T:$U,2,0)<=(VLOOKUP($AB3,药材与丹炉!$N:$O,2,0)+8)-($J3+IFERROR(IF($N3="",0,$N3),0)+IFERROR(IF($S3="",0,$S3),0)+IFERROR(IF($W3="",0,$W3),0)),1,2),1) -> 1 | AK3: =OR(NOT(IFERROR(OR($L3="",AND($L3<>"",$L3>0,VLOOKUP($AB3,药材与丹炉!$N:$O,2,0)=6)),0)),AND($L3<>"",$L3>0,OR(VLOOKUP($AB3,药材与丹炉!$N:$Q,4,0)-2<$N3,$N3="")),AND($U3<>"",$U3>0,OR(VLOOKUP($AB3,药材与丹炉!$N:$Q,4,0)-3<$W3,$W3="")),NOT(OR(AND($Q3<>"",$S3<>"",VLOOKUP($AB3,药材与丹炉!$N:$Q,4,0)-3>=$S3),$P3="")),NOT(OR(AND($H3<>"",$J3<>"",VLOOKUP($AB3,药材与丹炉!$N:$Q,4,0)-1>=$J3),$G3="")),NOT(OR($U3="",AND($U3<>"",$U3>0))),NOT(OR($Y3="",IF($Z3<>"",IFERROR(IF(VLOOKUP($Z3,药材与丹炉!$B:$D,3,0)=-1,$X3=1,IF(VLOOKUP($Z3,药材与丹炉!$B:$D,3,0)=1,$X3=2,$X3=0)),0),0))),$AC3="爆炸",(VLOOKUP($AB3,药材与丹炉!$N:$O,2,0)+8)<$AD3) -> FALSE
A4: 5003 | B4: 1 | C4: 生骨丹 | D4: 999 | E4: 生命值+35/丹毒+1 | F4: 1 | G4: 活血 | H4: 1 | I4: 天青花 | J4: =IFERROR(CEILING($H4/VLOOKUP($I4,药材与丹炉!$B:$H,COLUMN(药材与丹炉!$H4)-1,0),1),"") -> 1 | K4: 活血 | L4: =IFERROR(IF($F4-$H4=0,"",$F4-$H4),"") | N4: =IFERROR(CEILING($L4/VLOOKUP($M4,药材与丹炉!$B:$H,COLUMN(药材与丹炉!$H4)-1,0),1),"") | O4: 3 | P4: 固元 | Q4: 3 | R4: 银月花 | S4: =IFERROR(CEILING($Q4/VLOOKUP($R4,药材与丹炉!$B:$H,COLUMN(药材与丹炉!$H4)-1,0),1),"") -> 3 | T4: =P4 -> 固元 | U4: =IFERROR(IF($O4-$Q4=0,"",$O4-$Q4),"") | W4: =IFERROR(CEILING($U4/VLOOKUP($V4,药材与丹炉!$B:$H,COLUMN(药材与丹炉!$H4)-1,0),1),"") | X4: =IF(IFERROR(IF(AND($J4>0,$J4<>""),VLOOKUP($I4,药材与丹炉!$B:$D,3,0),0),0)+IFERROR(IF(AND($N4>0,$N4<>""),VLOOKUP($M4,药材与丹炉!$B:$D,3,0),0),0)+IFERROR(IF(AND($S4>0,$S4<>""),VLOOKUP($R4,药材与丹炉!$B:$D,3,0),0),0)+IFERROR(IF(AND($W4>0,$W4<>""),VLOOKUP($V4,药材与丹炉!$B:$D,3,0),0),0)>0,1,IF(IFERROR(IF(AND($J4>0,$J4<>""),VLOOKUP($I4,药材与丹炉!$B:$D,3,0),0),0)+IFERROR(IF(AND($N4>0,$N4<>""),VLOOKUP($M4,药材与丹炉!$B:$D,3,0),0),0)+IFERROR(IF(AND($S4>0,$S4<>""),VLOOKUP($R4,药材与丹炉!$B:$D,3,0),0),0)+IFERROR(IF(AND($W4>0,$W4<>""),VLOOKUP($V4,药材与丹炉!$B:$D,3,0),0),0)<0,2,0)) -> 0 | Y4: 1 | Z4: 凝血草 | AA4: =IFERROR($Y4/VLOOKUP($Z4,药材与丹炉!$B:$H,COLUMN(药材与丹炉!$H4)-1,0),"") -> 1 | AB4: 普通丹炉 | AC4: =IFERROR(IF($B4-VLOOKUP($AB4,药材与丹炉!$N:$P,2,0)<0,IF($AO$1="是",0,1),IF($B4-VLOOKUP($AB4,药材与丹炉!$N:$P,2,0)=0,2,IF($B4-VLOOKUP($AB4,药材与丹炉!$N:$P,2,0)=1,40,IF($B4-VLOOKUP($AB4,药材与丹炉!$N:$P,2,0)=2,80,"爆炸")))),"") -> 2 | AD4: =IFERROR($J4+IFERROR(IF($N4="",0,$N4),0)+IFERROR(IF($S4="",0,$S4),0)+IFERROR(IF($W4="",0,$W4),0)+IFERROR(IF($AA4="",0,$AA4),0),"") -> 5 | AE4: =IFERROR($J4*VLOOKUP($I4,药材与丹炉!$B:$K,10,0),0)+IFERROR($N4*VLOOKUP($M4,药材与丹炉!$B:$K,10,0),0)+IFERROR($S4*VLOOKUP($R4,药材与丹炉!$B:$K,10,0),0)+IFERROR($W4*VLOOKUP($V4,药材与丹炉!$B:$K,10,0),0)+IFERROR($AA4*VLOOKUP($Z4,药材与丹炉!$B:$K,10,0),0)+IFERROR($AC4*VLOOKUP($AB4,药材与丹炉!$N:$P,3,0)/100,0) -> 57 | AF4: 106 | AG4: =$AF4-$AE4 -> 49 | AH4: =$AF4*$AM$1*$AM$21 -> 212 | AI4: =$AH4-$AE4 -> 155 | AJ4: =IFERROR(IF($Y4/VLOOKUP($Y4,药材与丹炉!$T:$U,2,0)<=(VLOOKUP($AB4,药材与丹炉!$N:$O,2,0)+8)-($J4+IFERROR(IF($N4="",0,$N4),0)+IFERROR(IF($S4="",0,$S4),0)+IFERROR(IF($W4="",0,$W4),0)),1,2),1) -> 1 | AK4: =OR(NOT(IFERROR(OR($L4="",AND($L4<>"",$L4>0,VLOOKUP($AB4,药材与丹炉!$N:$O,2,0)=6)),0)),AND($L4<>"",$L4>0,OR(VLOOKUP($AB4,药材与丹炉!$N:$Q,4,0)-2<$N4,$N4="")),AND($U4<>"",$U4>0,OR(VLOOKUP($AB4,药材与丹炉!$N:$Q,4,0)-3<$W4,$W4="")),NOT(OR(AND($Q4<>"",$S4<>"",VLOOKUP($AB4,药材与丹炉!$N:$Q,4,0)-3>=$S4),$P4="")),NOT(OR(AND($H4<>"",$J4<>"",VLOOKUP($AB4,药材与丹炉!$N:$Q,4,0)-1>=$J4),$G4="")),NOT(OR($U4="",AND($U4<>"",$U4>0))),NOT(OR($Y4="",IF($Z4<>"",IFERROR(IF(VLOOKUP($Z4,药材与丹炉!$B:$D,3,0)=-1,$X4=1,IF(VLOOKUP($Z4,药材与丹炉!$B:$D,3,0)=1,$X4=2,$X4=0)),0),0))),$AC4="爆炸",(VLOOKUP($AB4,药材与丹炉!$N:$O,2,0)+8)<$AD4) -> FALSE | AL4: 价值与价格： | AM4: 丹药价格是丹药价值的货币表现 | AP4: 草药价格可以去药材与丹炉页面单独调整
A5: 5004 | B5: 1 | C5: 冰心丹 | D5: 30 | E5: 心境+1 | F5: 6 | G5: 聚元 | H5: 6 | I5: 恒心草 | J5: =IFERROR(CEILING($H5/VLOOKUP($I5,药材与丹炉!$B:$H,COLUMN(药材与丹炉!$H5)-1,0),1),"") -> 6 | K5: 聚元 | L5: =IFERROR(IF($F5-$H5=0,"",$F5-$H5),"") | N5: =IFERROR(CEILING($L5/VLOOKUP($M5,药材与丹炉!$B:$H,COLUMN(药材与丹炉!$H5)-1,0),1),"") | O5: 3 | P5: 清心 | Q5: 3 | R5: 宁心草 | S5: =IFERROR(CEILING($Q5/VLOOKUP($R5,药材与丹炉!$B:$H,COLUMN(药材与丹炉!$H5)-1,0),1),"") -> 3 | T5: =P5 -> 清心 | U5: =IFERROR(IF($O5-$Q5=0,"",$O5-$Q5),"") | W5: =IFERROR(CEILING($U5/VLOOKUP($V5,药材与丹炉!$B:$H,COLUMN(药材与丹炉!$H5)-1,0),1),"") | X5: =IF(IFERROR(IF(AND($J5>0,$J5<>""),VLOOKUP($I5,药材与丹炉!$B:$D,3,0),0),0)+IFERROR(IF(AND($N5>0,$N5<>""),VLOOKUP($M5,药材与丹炉!$B:$D,3,0),0),0)+IFERROR(IF(AND($S5>0,$S5<>""),VLOOKUP($R5,药材与丹炉!$B:$D,3,0),0),0)+IFERROR(IF(AND($W5>0,$W5<>""),VLOOKUP($V5,药材与丹炉!$B:$D,3,0),0),0)>0,1,IF(IFERROR(IF(AND($J5>0,$J5<>""),VLOOKUP($I5,药材与丹炉!$B:$D,3,0),0),0)+IFERROR(IF(AND($N5>0,$N5<>""),VLOOKUP($M5,药材与丹炉!$B:$D,3,0),0),0)+IFERROR(IF(AND($S5>0,$S5<>""),VLOOKUP($R5,药材与丹炉!$B:$D,3,0),0),0)+IFERROR(IF(AND($W5>0,$W5<>""),VLOOKUP($V5,药材与丹炉!$B:$D,3,0),0),0)<0,2,0)) -> 2 | Y5: 3 | Z5: 天元果 | AA5: =IFERROR($Y5/VLOOKUP($Z5,药材与丹炉!$B:$H,COLUMN(药材与丹炉!$H5)-1,0),"") -> 1 | AB5: 陨铁炉 | AC5: =IFERROR(IF($B5-VLOOKUP($AB5,药材与丹炉!$N:$P,2,0)<0,IF($AO$1="是",0,1),IF($B5-VLOOKUP($AB5,药材与丹炉!$N:$P,2,0)=0,2,IF($B5-VLOOKUP($AB5,药材与丹炉!$N:$P,2,0)=1,40,IF($B5-VLOOKUP($AB5,药材与丹炉!$N:$P,2,0)=2,80,"爆炸")))),"") -> 1 | AD5: =IFERROR($J5+IFERROR(IF($N5="",0,$N5),0)+IFERROR(IF($S5="",0,$S5),0)+IFERROR(IF($W5="",0,$W5),0)+IFERROR(IF($AA5="",0,$AA5),0),"") -> 10 | AE5: =IFERROR($J5*VLOOKUP($I5,药材与丹炉!$B:$K,10,0),0)+IFERROR($N5*VLOOKUP($M5,药材与丹炉!$B:$K,10,0),0)+IFERROR($S5*VLOOKUP($R5,药材与丹炉!$B:$K,10,0),0)+IFERROR($W5*VLOOKUP($V5,药材与丹炉!$B:$K,10,0),0)+IFERROR($AA5*VLOOKUP($Z5,药材与丹炉!$B:$K,10,0),0)+IFERROR($AC5*VLOOKUP($AB5,药材与丹炉!$N:$P,3,0)/100,0) -> 129 | AF5: 168 | AG5: =$AF5-$AE5 -> 39 | AH5: =$AF5*$AM$1*$AM$21 -> 336 | AI5: =$AH5-$AE5 -> 207 | AJ5: =IFERROR(IF($Y5/VLOOKUP($Y5,药材与丹炉!$T:$U,2,0)<=(VLOOKUP($AB5,药材与丹炉!$N:$O,2,0)+8)-($J5+IFERROR(IF($N5="",0,$N5),0)+IFERROR(IF($S5="",0,$S5),0)+IFERROR(IF($W5="",0,$W5),0)),1,2),1) -> 2 | AK5: =OR(NOT(IFERROR(OR($L5="",AND($L5<>"",$L5>0,VLOOKUP($AB5,药材与丹炉!$N:$O,2,0)=6)),0)),AND($L5<>"",$L5>0,OR(VLOOKUP($AB5,药材与丹炉!$N:$Q,4,0)-2<$N5,$N5="")),AND($U5<>"",$U5>0,OR(VLOOKUP($AB5,药材与丹炉!$N:$Q,4,0)-3<$W5,$W5="")),NOT(OR(AND($Q5<>"",$S5<>"",VLOOKUP($AB5,药材与丹炉!$N:$Q,4,0)-3>=$S5),$P5="")),NOT(OR(AND($H5<>"",$J5<>"",VLOOKUP($AB5,药材与丹炉!$N:$Q,4,0)-1>=$J5),$G5="")),NOT(OR($U5="",AND($U5<>"",$U5>0))),NOT(OR($Y5="",IF($Z5<>"",IFERROR(IF(VLOOKUP($Z5,药材与丹炉!$B:$D,3,0)=-1,$X5=1,IF(VLOOKUP($Z5,药材与丹炉!$B:$D,3,0)=1,$X5=2,$X5=0)),0),0))),$AC5="爆炸",(VLOOKUP($AB5,药材与丹炉!$N:$O,2,0)+8)<$AD5) -> FALSE | AL5: 价值差： | AM5: 丹药原价-炼制成本 (中草阁购买草药价)
A6: 5005 | B6: 1 | C6: 凝神丹 | D6: 50 | E6: 下场战斗中神识+1/丹毒+5 | F6: 3 | G6: 振气 | H6: 3 | I6: 宁心草 | J6: =IFERROR(CEILING($H6/VLOOKUP($I6,药材与丹炉!$B:$H,COLUMN(药材与丹炉!$H6)-1,0),1),"") -> 3 | K6: 振气 | L6: =IFERROR(IF($F6-$H6=0,"",$F6-$H6),"") | N6: =IFERROR(CEILING($L6/VLOOKUP($M6,药材与丹炉!$B:$H,COLUMN(药材与丹炉!$H6)-1,0),1),"") | O6: 1 | P6: 凝神 | Q6: 1 | R6: 宁神花 | S6: =IFERROR(CEILING($Q6/VLOOKUP($R6,药材与丹炉!$B:$H,COLUMN(药材与丹炉!$H6)-1,0),1),"") -> 1 | T6: =P6 -> 凝神 | U6: =IFERROR(IF($O6-$Q6=0,"",$O6-$Q6),"") | W6: =IFERROR(CEILING($U6/VLOOKUP($V6,药材与丹炉!$B:$H,COLUMN(药材与丹炉!$H6)-1,0),1),"") | X6: =IF(IFERROR(IF(AND($J6>0,$J6<>""),VLOOKUP($I6,药材与丹炉!$B:$D,3,0),0),0)+IFERROR(IF(AND($N6>0,$N6<>""),VLOOKUP($M6,药材与丹炉!$B:$D,3,0),0),0)+IFERROR(IF(AND($S6>0,$S6<>""),VLOOKUP($R6,药材与丹炉!$B:$D,3,0),0),0)+IFERROR(IF(AND($W6>0,$W6<>""),VLOOKUP($V6,药材与丹炉!$B:$D,3,0),0),0)>0,1,IF(IFERROR(IF(AND($J6>0,$J6<>""),VLOOKUP($I6,药材与丹炉!$B:$D,3,0),0),0)+IFERROR(IF(AND($N6>0,$N6<>""),VLOOKUP($M6,药材与丹炉!$B:$D,3,0),0),0)+IFERROR(IF(AND($S6>0,$S6<>""),VLOOKUP($R6,药材与丹炉!$B:$D,3,0),0),0)+IFERROR(IF(AND($W6>0,$W6<>""),VLOOKUP($V6,药材与丹炉!$B:$D,3,0),0),0)<0,2,0)) -> 2 | Y6: 3 | Z6: 流莹草 | AA6: =IFERROR($Y6/VLOOKUP($Z6,药材与丹炉!$B:$H,COLUMN(药材与丹炉!$H6)-1,0),"") -> 3 | AB6: 普通丹炉 | AC6: =IFERROR(IF($B6-VLOOKUP($AB6,药材与丹炉!$N:$P,2,0)<0,IF($AO$1="是",0,1),IF($B6-VLOOKUP($AB6,药材与丹炉!$N:$P,2,0)=0,2,IF($B6-VLOOKUP($AB6,药材与丹炉!$N:$P,2,0)=1,40,IF($B6-VLOOKUP($AB6,药材与丹炉!$N:$P,2,0)=2,80,"爆炸")))),"") -> 2 | AD6: =IFERROR($J6+IFERROR(IF($N6="",0,$N6),0)+IFERROR(IF($S6="",0,$S6),0)+IFERROR(IF($W6="",0,$W6),0)+IFERROR(IF($AA6="",0,$AA6),0),"") -> 7 | AE6: =IFERROR($J6*VLOOKUP($I6,药材与丹炉!$B:$K,10,0),0)+IFERROR($N6*VLOOKUP($M6,药材与丹炉!$B:$K,10,0),0)+IFERROR($S6*VLOOKUP($R6,药材与丹炉!$B:$K,10,0),0)+IFERROR($W6*VLOOKUP($V6,药材与丹炉!$B:$K,10,0),0)+IFERROR($AA6*VLOOKUP($Z6,药材与丹炉!$B:$K,10,0),0)+IFERROR($AC6*VLOOKUP($AB6,药材与丹炉!$N:$P,3,0)/100,0) -> 75 | AF6: 118 | AG6: =$AF6-$AE6 -> 43 | AH6: =$AF6*$AM$1*$AM$21 -> 236 | AI6: =$AH6-$AE6 -> 161 | AJ6: =IFERROR(IF($Y6/VLOOKUP($Y6,药材与丹炉!$T:$U,2,0)<=(VLOOKUP($AB6,药材与丹炉!$N:$O,2,0)+8)-($J6+IFERROR(IF($N6="",0,$N6),0)+IFERROR(IF($S6="",0,$S6),0)+IFERROR(IF($W6="",0,$W6),0)),1,2),1) -> 1 | AK6: =OR(NOT(IFERROR(OR($L6="",AND($L6<>"",$L6>0,VLOOKUP($AB6,药材与丹炉!$N:$O,2,0)=6)),0)),AND($L6<>"",$L6>0,OR(VLOOKUP($AB6,药材与丹炉!$N:$Q,4,0)-2<$N6,$N6="")),AND($U6<>"",$U6>0,OR(VLOOKUP($AB6,药材与丹炉!$N:$Q,4,0)-3<$W6,$W6="")),NOT(OR(AND($Q6<>"",$S6<>"",VLOOKUP($AB6,药材与丹炉!$N:$Q,4,0)-3>=$S6),$P6="")),NOT(OR(AND($H6<>"",$J6<>"",VLOOKUP($AB6,药材与丹炉!$N:$Q,4,0)-1>=$J6),$G6="")),NOT(OR($U6="",AND($U6<>"",$U6>0))),NOT(OR($Y6="",IF($Z6<>"",IFERROR(IF(VLOOKUP($Z6,药材与丹炉!$B:$D,3,0)=-1,$X6=1,IF(VLOOKUP($Z6,药材与丹炉!$B:$D,3,0)=1,$X6=2,$X6=0)),0),0))),$AC6="爆炸",(VLOOKUP($AB6,药材与丹炉!$N:$O,2,0)+8)<$AD6) -> FALSE | AL6: 价格差： | AM6: 交易价格-炼制成本 (中草阁购买草药价)
A7: 5006 | B7: 1 | C7: 龙虎丹 | D7: 50 | E7: 下场战斗第一回合造成的伤害+1/丹毒+5 | F7: 6 | G7: 振气 | H7: 6 | I7: 宁心草 | J7: =IFERROR(CEILING($H7/VLOOKUP($I7,药材与丹炉!$B:$H,COLUMN(药材与丹炉!$H7)-1,0),1),"") -> 6 | K7: 振气 | L7: =IFERROR(IF($F7-$H7=0,"",$F7-$H7),"") | N7: =IFERROR(CEILING($L7/VLOOKUP($M7,药材与丹炉!$B:$H,COLUMN(药材与丹炉!$H7)-1,0),1),"") | O7: 3 | P7: 混元 | Q7: 3 | R7: 凝血草 | S7: =IFERROR(CEILING($Q7/VLOOKUP($R7,药材与丹炉!$B:$H,COLUMN(药材与丹炉!$H7)-1,0),1),"") -> 3 | T7: =P7 -> 混元 | U7: =IFERROR(IF($O7-$Q7=0,"",$O7-$Q7),"") | W7: =IFERROR(CEILING($U7/VLOOKUP($V7,药材与丹炉!$B:$H,COLUMN(药材与丹炉!$H7)-1,0),1),"") | X7: =IF(IFERROR(IF(AND($J7>0,$J7<>""),VLOOKUP($I7,药材与丹炉!$B:$D,3,0),0),0)+IFERROR(IF(AND($N7>0,$N7<>""),VLOOKUP($M7,药材与丹炉!$B:$D,3,0),0),0)+IFERROR(IF(AND($S7>0,$S7<>""),VLOOKUP($R7,药材与丹炉!$B:$D,3,0),0),0)+IFERROR(IF(AND($W7>0,$W7<>""),VLOOKUP($V7,药材与丹炉!$B:$D,3,0),0),0)>0,1,IF(IFERROR(IF(AND($J7>0,$J7<>""),VLOOKUP($I7,药材与丹炉!$B:$D,3,0),0),0)+IFERROR(IF(AND($N7>0,$N7<>""),VLOOKUP($M7,药材与丹炉!$B:$D,3,0),0),0)+IFERROR(IF(AND($S7>0,$S7<>""),VLOOKUP($R7,药材与丹炉!$B:$D,3,0),0),0)+IFERROR(IF(AND($W7>0,$W7<>""),VLOOKUP($V7,药材与丹炉!$B:$D,3,0),0),0)<0,2,0)) -> 2 | Y7: 1 | Z7: 流莹草 | AA7: =IFERROR($Y7/VLOOKUP($Z7,药材与丹炉!$B:$H,COLUMN(药材与丹炉!$H7)-1,0),"") -> 1 | AB7: 陨铁炉 | AC7: =IFERROR(IF($B7-VLOOKUP($AB7,药材与丹炉!$N:$P,2,0)<0,IF($AO$1="是",0,1),IF($B7-VLOOKUP($AB7,药材与丹炉!$N:$P,2,0)=0,2,IF($B7-VLOOKUP($AB7,药材与丹炉!$N:$P,2,0)=1,40,IF($B7-VLOOKUP($AB7,药材与丹炉!$N:$P,2,0)=2,80,"爆炸")))),"") -> 1 | AD7: =IFERROR($J7+IFERROR(IF($N7="",0,$N7),0)+IFERROR(IF($S7="",0,$S7),0)+IFERROR(IF($W7="",0,$W7),0)+IFERROR(IF($AA7="",0,$AA7),0),"") -> 10 | AE7: =IFERROR($J7*VLOOKUP($I7,药材与丹炉!$B:$K,10,0),0)+IFERROR($N7*VLOOKUP($M7,药材与丹炉!$B:$K,10,0),0)+IFERROR($S7*VLOOKUP($R7,药材与丹炉!$B:$K,10,0),0)+IFERROR($W7*VLOOKUP($V7,药材与丹炉!$B:$K,10,0),0)+IFERROR($AA7*VLOOKUP($Z7,药材与丹炉!$B:$K,10,0),0)+IFERROR($AC7*VLOOKUP($AB7,药材与丹炉!$N:$P,3,0)/100,0) -> 102 | AF7: 143 | AG7: =$AF7-$AE7 -> 41 | AH7: =$AF7*$AM$1*$AM$21 -> 286 | AI7: =$AH7-$AE7 -> 184 | AJ7: =IFERROR(IF($Y7/VLOOKUP($Y7,药材与丹炉!$T:$U,2,0)<=(VLOOKUP($AB7,药材与丹炉!$N:$O,2,0)+8)-($J7+IFERROR(IF($N7="",0,$N7),0)+IFERROR(IF($S7="",0,$S7),0)+IFERROR(IF($W7="",0,$W7),0)),1,2),1) -> 1 | AK7: =OR(NOT(IFERROR(OR($L7="",AND($L7<>"",$L7>0,VLOOKUP($AB7,药材与丹炉!$N:$O,2,0)=6)),0)),AND($L7<>"",$L7>0,OR(VLOOKUP($AB7,药材与丹炉!$N:$Q,4,0)-2<$N7,$N7="")),AND($U7<>"",$U7>0,OR(VLOOKUP($AB7,药材与丹炉!$N:$Q,4,0)-3<$W7,$W7="")),NOT(OR(AND($Q7<>"",$S7<>"",VLOOKUP($AB7,药材与丹炉!$N:$Q,4,0)-3>=$S7),$P7="")),NOT(OR(AND($H7<>"",$J7<>"",VLOOKUP($AB7,药材与丹炉!$N:$Q,4,0)-1>=$J7),$G7="")),NOT(OR($U7="",AND($U7<>"",$U7>0))),NOT(OR($Y7="",IF($Z7<>"",IFERROR(IF(VLOOKUP($Z7,药材与丹炉!$B:$D,3,0)=-1,$X7=1,IF(VLOOKUP($Z7,药材与丹炉!$B:$D,3,0)=1,$X7=2,$X7=0)),0),0))),$AC7="爆炸",(VLOOKUP($AB7,药材与丹炉!$N:$O,2,0)+8)<$AD7) -> FALSE | AL7: 倍率说明
A8: 5007 | B8: 1 | C8: 引灵丹 | D8: 50 | E8: 下场战斗开始时，额外抽1张灵气牌/丹毒+5 | F8: 3 | G8: 振气 | H8: 3 | I8: 宁心草 | J8: =IFERROR(CEILING($H8/VLOOKUP($I8,药材与丹炉!$B:$H,COLUMN(药材与丹炉!$H8)-1,0),1),"") -> 3 | K8: 振气 | L8: =IFERROR(IF($F8-$H8=0,"",$F8-$H8),"") | N8: =IFERROR(CEILING($L8/VLOOKUP($M8,药材与丹炉!$B:$H,COLUMN(药材与丹炉!$H8)-1,0),1),"") | O8: 3 | P8: 聚灵 | Q8: 3 | R8: 蛇涎果 | S8: =IFERROR(CEILING($Q8/VLOOKUP($R8,药材与丹炉!$B:$H,COLUMN(药材与丹炉!$H8)-1,0),1),"") -> 1 | T8: =P8 -> 聚灵 | U8: =IFERROR(IF($O8-$Q8=0,"",$O8-$Q8),"") | W8: =IFERROR(CEILING($U8/VLOOKUP($V8,药材与丹炉!$B:$H,COLUMN(药材与丹炉!$H8)-1,0),1),"") | X8: =IF(IFERROR(IF(AND($J8>0,$J8<>""),VLOOKUP($I8,药材与丹炉!$B:$D,3,0),0),0)+IFERROR(IF(AND($N8>0,$N8<>""),VLOOKUP($M8,药材与丹炉!$B:$D,3,0),0),0)+IFERROR(IF(AND($S8>0,$S8<>""),VLOOKUP($R8,药材与丹炉!$B:$D,3,0),0),0)+IFERROR(IF(AND($W8>0,$W8<>""),VLOOKUP($V8,药材与丹炉!$B:$D,3,0),0),0)>0,1,IF(IFERROR(IF(AND($J8>0,$J8<>""),VLOOKUP($I8,药材与丹炉!$B:$D,3,0),0),0)+IFERROR(IF(AND($N8>0,$N8<>""),VLOOKUP($M8,药材与丹炉!$B:$D,3,0),0),0)+IFERROR(IF(AND($S8>0,$S8<>""),VLOOKUP($R8,药材与丹炉!$B:$D,3,0),0),0)+IFERROR(IF(AND($W8>0,$W8<>""),VLOOKUP($V8,药材与丹炉!$B:$D,3,0),0),0)<0,2,0)) -> 0 | Y8: 1 | Z8: 恒心草 | AA8: =IFERROR($Y8/VLOOKUP($Z8,药材与丹炉!$B:$H,COLUMN(药材与丹炉!$H8)-1,0),"") -> 1 | AB8: 普通丹炉 | AC8: =IFERROR(IF($B8-VLOOKUP($AB8,药材与丹炉!$N:$P,2,0)<0,IF($AO$1="是",0,1),IF($B8-VLOOKUP($AB8,药材与丹炉!$N:$P,2,0)=0,2,IF($B8-VLOOKUP($AB8,药材与丹炉!$N:$P,2,0)=1,40,IF($B8-VLOOKUP($AB8,药材与丹炉!$N:$P,2,0)=2,80,"爆炸")))),"") -> 2 | AD8: =IFERROR($J8+IFERROR(IF($N8="",0,$N8),0)+IFERROR(IF($S8="",0,$S8),0)+IFERROR(IF($W8="",0,$W8),0)+IFERROR(IF($AA8="",0,$AA8),0),"") -> 5 | AE8: =IFERROR($J8*VLOOKUP($I8,药材与丹炉!$B:$K,10,0),0)+IFERROR($N8*VLOOKUP($M8,药材与丹炉!$B:$K,10,0),0)+IFERROR($S8*VLOOKUP($R8,药材与丹炉!$B:$K,10,0),0)+IFERROR($W8*VLOOKUP($V8,药材与丹炉!$B:$K,10,0),0)+IFERROR($AA8*VLOOKUP($Z8,药材与丹炉!$B:$K,10,0),0)+IFERROR($AC8*VLOOKUP($AB8,药材与丹炉!$N:$P,3,0)/100,0) -> 84 | AF8: 143 | AG8: =$AF8-$AE8 -> 59 | AH8: =$AF8*$AM$1*$AM$21 -> 286 | AI8: =$AH8-$AE8 -> 202 | AJ8: =IFERROR(IF($Y8/VLOOKUP($Y8,药材与丹炉!$T:$U,2,0)<=(VLOOKUP($AB8,药材与丹炉!$N:$O,2,0)+8)-($J8+IFERROR(IF($N8="",0,$N8),0)+IFERROR(IF($S8="",0,$S8),0)+IFERROR(IF($W8="",0,$W8),0)),1,2),1) -> 1 | AK8: =OR(NOT(IFERROR(OR($L8="",AND($L8<>"",$L8>0,VLOOKUP($AB8,药材与丹炉!$N:$O,2,0)=6)),0)),AND($L8<>"",$L8>0,OR(VLOOKUP($AB8,药材与丹炉!$N:$Q,4,0)-2<$N8,$N8="")),AND($U8<>"",$U8>0,OR(VLOOKUP($AB8,药材与丹炉!$N:$Q,4,0)-3<$W8,$W8="")),NOT(OR(AND($Q8<>"",$S8<>"",VLOOKUP($AB8,药材与丹炉!$N:$Q,4,0)-3>=$S8),$P8="")),NOT(OR(AND($H8<>"",$J8<>"",VLOOKUP($AB8,药材与丹炉!$N:$Q,4,0)-1>=$J8),$G8="")),NOT(OR($U8="",AND($U8<>"",$U8>0))),NOT(OR($Y8="",IF($Z8<>"",IFERROR(IF(VLOOKUP($Z8,药材与丹炉!$B:$D,3,0)=-1,$X8=1,IF(VLOOKUP($Z8,药材与丹炉!$B:$D,3,0)=1,$X8=2,$X8=0)),0),0))),$AC8="爆炸",(VLOOKUP($AB8,药材与丹炉!$N:$O,2,0)+8)<$AD8) -> FALSE | AL8: 0.475 | AM8: 在坊市将物品卖给不感兴趣的NPC【坊市95折】
A9: 5008 | B9: 1 | C9: 聚甲丹 | D9: 50 | E9: 下场战斗开始时，获得【护罩】*1/丹毒+5 | F9: 6 | G9: 御气 | H9: 6 | I9: 地黄参 | J9: =IFERROR(CEILING($H9/VLOOKUP($I9,药材与丹炉!$B:$H,COLUMN(药材与丹炉!$H9)-1,0),1),"") -> 2 | K9: 御气 | L9: =IFERROR(IF($F9-$H9=0,"",$F9-$H9),"") | N9: =IFERROR(CEILING($L9/VLOOKUP($M9,药材与丹炉!$B:$H,COLUMN(药材与丹炉!$H9)-1,0),1),"") | O9: 3 | P9: 固元 | Q9: 3 | R9: 银月花 | S9: =IFERROR(CEILING($Q9/VLOOKUP($R9,药材与丹炉!$B:$H,COLUMN(药材与丹炉!$H9)-1,0),1),"") -> 3 | T9: =P9 -> 固元 | U9: =IFERROR(IF($O9-$Q9=0,"",$O9-$Q9),"") | W9: =IFERROR(CEILING($U9/VLOOKUP($V9,药材与丹炉!$B:$H,COLUMN(药材与丹炉!$H9)-1,0),1),"") | X9: =IF(IFERROR(IF(AND($J9>0,$J9<>""),VLOOKUP($I9,药材与丹炉!$B:$D,3,0),0),0)+IFERROR(IF(AND($N9>0,$N9<>""),VLOOKUP($M9,药材与丹炉!$B:$D,3,0),0),0)+IFERROR(IF(AND($S9>0,$S9<>""),VLOOKUP($R9,药材与丹炉!$B:$D,3,0),0),0)+IFERROR(IF(AND($W9>0,$W9<>""),VLOOKUP($V9,药材与丹炉!$B:$D,3,0),0),0)>0,1,IF(IFERROR(IF(AND($J9>0,$J9<>""),VLOOKUP($I9,药材与丹炉!$B:$D,3,0),0),0)+IFERROR(IF(AND($N9>0,$N9<>""),VLOOKUP($M9,药材与丹炉!$B:$D,3,0),0),0)+IFERROR(IF(AND($S9>0,$S9<>""),VLOOKUP($R9,药材与丹炉!$B:$D,3,0),0),0)+IFERROR(IF(AND($W9>0,$W9<>""),VLOOKUP($V9,药材与丹炉!$B:$D,3,0),0),0)<0,2,0)) -> 0 | Y9: 1 | Z9: 恒心草 | AA9: =IFERROR($Y9/VLOOKUP($Z9,药材与丹炉!$B:$H,COLUMN(药材与丹炉!$H9)-1,0),"") -> 1 | AB9: 普通丹炉 | AC9: =IFERROR(IF($B9-VLOOKUP($AB9,药材与丹炉!$N:$P,2,0)<0,IF($AO$1="是",0,1),IF($B9-VLOOKUP($AB9,药材与丹炉!$N:$P,2,0)=0,2,IF($B9-VLOOKUP($AB9,药材与丹炉!$N:$P,2,0)=1,40,IF($B9-VLOOKUP($AB9,药材与丹炉!$N:$P,2,0)=2,80,"爆炸")))),"") -> 2 | AD9: =IFERROR($J9+IFERROR(IF($N9="",0,$N9),0)+IFERROR(IF($S9="",0,$S9),0)+IFERROR(IF($W9="",0,$W9),0)+IFERROR(IF($AA9="",0,$AA9),0),"") -> 6 | AE9: =IFERROR($J9*VLOOKUP($I9,药材与丹炉!$B:$K,10,0),0)+IFERROR($N9*VLOOKUP($M9,药材与丹炉!$B:$K,10,0),0)+IFERROR($S9*VLOOKUP($R9,药材与丹炉!$B:$K,10,0),0)+IFERROR($W9*VLOOKUP($V9,药材与丹炉!$B:$K,10,0),0)+IFERROR($AA9*VLOOKUP($Z9,药材与丹炉!$B:$K,10,0),0)+IFERROR($AC9*VLOOKUP($AB9,药材与丹炉!$N:$P,3,0)/100,0) -> 120 | AF9: 187 | AG9: =$AF9-$AE9 -> 67 | AH9: =$AF9*$AM$1*$AM$21 -> 374 | AI9: =$AH9-$AE9 -> 254 | AJ9: =IFERROR(IF($Y9/VLOOKUP($Y9,药材与丹炉!$T:$U,2,0)<=(VLOOKUP($AB9,药材与丹炉!$N:$O,2,0)+8)-($J9+IFERROR(IF($N9="",0,$N9),0)+IFERROR(IF($S9="",0,$S9),0)+IFERROR(IF($W9="",0,$W9),0)),1,2),1) -> 1 | AK9: =OR(NOT(IFERROR(OR($L9="",AND($L9<>"",$L9>0,VLOOKUP($AB9,药材与丹炉!$N:$O,2,0)=6)),0)),AND($L9<>"",$L9>0,OR(VLOOKUP($AB9,药材与丹炉!$N:$Q,4,0)-2<$N9,$N9="")),AND($U9<>"",$U9>0,OR(VLOOKUP($AB9,药材与丹炉!$N:$Q,4,0)-3<$W9,$W9="")),NOT(OR(AND($Q9<>"",$S9<>"",VLOOKUP($AB9,药材与丹炉!$N:$Q,4,0)-3>=$S9),$P9="")),NOT(OR(AND($H9<>"",$J9<>"",VLOOKUP($AB9,药材与丹炉!$N:$Q,4,0)-1>=$J9),$G9="")),NOT(OR($U9="",AND($U9<>"",$U9>0))),NOT(OR($Y9="",IF($Z9<>"",IFERROR(IF(VLOOKUP($Z9,药材与丹炉!$B:$D,3,0)=-1,$X9=1,IF(VLOOKUP($Z9,药材与丹炉!$B:$D,3,0)=1,$X9=2,$X9=0)),0),0))),$AC9="爆炸",(VLOOKUP($AB9,药材与丹炉!$N:$O,2,0)+8)<$AD9) -> FALSE | AL9: 0.5 | AM9: 在非坊市地区将物品卖给不感兴趣NPC的标价
A10: 5009 | B10: 1 | C10: 龟灵丹 | D10: 50 | E10: 下场战斗开始时，获得【减伤】*1/丹毒+5 | F10: 3 | G10: 御气 | H10: 3 | I10: 地黄参 | J10: =IFERROR(CEILING($H10/VLOOKUP($I10,药材与丹炉!$B:$H,COLUMN(药材与丹炉!$H10)-1,0),1),"") -> 1 | K10: 御气 | L10: =IFERROR(IF($F10-$H10=0,"",$F10-$H10),"") | N10: =IFERROR(CEILING($L10/VLOOKUP($M10,药材与丹炉!$B:$H,COLUMN(药材与丹炉!$H10)-1,0),1),"") | O10: 4 | P10: 混元 | Q10: 4 | R10: 凝血草 | S10: =IFERROR(CEILING($Q10/VLOOKUP($R10,药材与丹炉!$B:$H,COLUMN(药材与丹炉!$H10)-1,0),1),"") -> 4 | T10: =P10 -> 混元 | U10: =IFERROR(IF($O10-$Q10=0,"",$O10-$Q10),"") | W10: =IFERROR(CEILING($U10/VLOOKUP($V10,药材与丹炉!$B:$H,COLUMN(药材与丹炉!$H10)-1,0),1),"") | X10: =IF(IFERROR(IF(AND($J10>0,$J10<>""),VLOOKUP($I10,药材与丹炉!$B:$D,3,0),0),0)+IFERROR(IF(AND($N10>0,$N10<>""),VLOOKUP($M10,药材与丹炉!$B:$D,3,0),0),0)+IFERROR(IF(AND($S10>0,$S10<>""),VLOOKUP($R10,药材与丹炉!$B:$D,3,0),0),0)+IFERROR(IF(AND($W10>0,$W10<>""),VLOOKUP($V10,药材与丹炉!$B:$D,3,0),0),0)>0,1,IF(IFERROR(IF(AND($J10>0,$J10<>""),VLOOKUP($I10,药材与丹炉!$B:$D,3,0),0),0)+IFERROR(IF(AND($N10>0,$N10<>""),VLOOKUP($M10,药材与丹炉!$B:$D,3,0),0),0)+IFERROR(IF(AND($S10>0,$S10<>""),VLOOKUP($R10,药材与丹炉!$B:$D,3,0),0),0)+IFERROR(IF(AND($W10>0,$W10<>""),VLOOKUP($V10,药材与丹炉!$B:$D,3,0),0),0)<0,2,0)) -> 1 | Y10: 3 | Z10: 宁神花 | AA10: =IFERROR($Y10/VLOOKUP($Z10,药材与丹炉!$B:$H,COLUMN(药材与丹炉!$H10)-1,0),"") -> 3 | AB10: 普通丹炉 | AC10: =IFERROR(IF($B10-VLOOKUP($AB10,药材与丹炉!$N:$P,2,0)<0,IF($AO$1="是",0,1),IF($B10-VLOOKUP($AB10,药材与丹炉!$N:$P,2,0)=0,2,IF($B10-VLOOKUP($AB10,药材与丹炉!$N:$P,2,0)=1,40,IF($B10-VLOOKUP($AB10,药材与丹炉!$N:$P,2,0)=2,80,"爆炸")))),"") -> 2 | AD10: =IFERROR($J10+IFERROR(IF($N10="",0,$N10),0)+IFERROR(IF($S10="",0,$S10),0)+IFERROR(IF($W10="",0,$W10),0)+IFERROR(IF($AA10="",0,$AA10),0),"") -> 8 | AE10: =IFERROR($J10*VLOOKUP($I10,药材与丹炉!$B:$K,10,0),0)+IFERROR($N10*VLOOKUP($M10,药材与丹炉!$B:$K,10,0),0)+IFERROR($S10*VLOOKUP($R10,药材与丹炉!$B:$K,10,0),0)+IFERROR($W10*VLOOKUP($V10,药材与丹炉!$B:$K,10,0),0)+IFERROR($AA10*VLOOKUP($Z10,药材与丹炉!$B:$K,10,0),0)+IFERROR($AC10*VLOOKUP($AB10,药材与丹炉!$N:$P,3,0)/100,0) -> 111 | AF10: 150 | AG10: =$AF10-$AE10 -> 39 | AH10: =$AF10*$AM$1*$AM$21 -> 300 | AI10: =$AH10-$AE10 -> 189 | AJ10: =IFERROR(IF($Y10/VLOOKUP($Y10,药材与丹炉!$T:$U,2,0)<=(VLOOKUP($AB10,药材与丹炉!$N:$O,2,0)+8)-($J10+IFERROR(IF($N10="",0,$N10),0)+IFERROR(IF($S10="",0,$S10),0)+IFERROR(IF($W10="",0,$W10),0)),1,2),1) -> 1 | AK10: =OR(NOT(IFERROR(OR($L10="",AND($L10<>"",$L10>0,VLOOKUP($AB10,药材与丹炉!$N:$O,2,0)=6)),0)),AND($L10<>"",$L10>0,OR(VLOOKUP($AB10,药材与丹炉!$N:$Q,4,0)-2<$N10,$N10="")),AND($U10<>"",$U10>0,OR(VLOOKUP($AB10,药材与丹炉!$N:$Q,4,0)-3<$W10,$W10="")),NOT(OR(AND($Q10<>"",$S10<>"",VLOOKUP($AB10,药材与丹炉!$N:$Q,4,0)-3>=$S10),$P10="")),NOT(OR(AND($H10<>"",$J10<>"",VLOOKUP($AB10,药材与丹炉!$N:$Q,4,0)-1>=$J10),$G10="")),NOT(OR($U10="",AND($U10<>"",$U10>0))),NOT(OR($Y10="",IF($Z10<>"",IFERROR(IF(VLOOKUP($Z10,药材与丹炉!$B:$D,3,0)=-1,$X10=1,IF(VLOOKUP($Z10,药材与丹炉!$B:$D,3,0)=1,$X10=2,$X10=0)),0),0))),$AC10="爆炸",(VLOOKUP($AB10,药材与丹炉!$N:$O,2,0)+8)<$AD10) -> FALSE | AL10: 0.9 | AM10: 灵药堂的收购价【灵药堂9折】
B11: 1 | C11: 一阶废丹 | D11: 999 | E11: 修为+132（需神秘贝壳）/丹毒+10 | F11: 1 | G11: 活血 | H11: 1 | I11: 银月花 | J11: =IFERROR(CEILING($H11/VLOOKUP($I11,药材与丹炉!$B:$H,COLUMN(药材与丹炉!$H11)-1,0),1),"") -> 1 | K11: 活血 | L11: =IFERROR(IF($F11-$H11=0,"",$F11-$H11),"") | N11: =IFERROR(CEILING($L11/VLOOKUP($M11,药材与丹炉!$B:$H,COLUMN(药材与丹炉!$H11)-1,0),1),"") | O11: 1 | P11: 培元 | Q11: 1 | R11: 流莹草 | S11: =IFERROR(CEILING($Q11/VLOOKUP($R11,药材与丹炉!$B:$H,COLUMN(药材与丹炉!$H11)-1,0),1),"") -> 1 | T11: =P11 -> 培元 | U11: =IFERROR(IF($O11-$Q11=0,"",$O11-$Q11),"") | W11: =IFERROR(CEILING($U11/VLOOKUP($V11,药材与丹炉!$B:$H,COLUMN(药材与丹炉!$H11)-1,0),1),"") | X11: =IF(IFERROR(IF(AND($J11>0,$J11<>""),VLOOKUP($I11,药材与丹炉!$B:$D,3,0),0),0)+IFERROR(IF(AND($N11>0,$N11<>""),VLOOKUP($M11,药材与丹炉!$B:$D,3,0),0),0)+IFERROR(IF(AND($S11>0,$S11<>""),VLOOKUP($R11,药材与丹炉!$B:$D,3,0),0),0)+IFERROR(IF(AND($W11>0,$W11<>""),VLOOKUP($V11,药材与丹炉!$B:$D,3,0),0),0)>0,1,IF(IFERROR(IF(AND($J11>0,$J11<>""),VLOOKUP($I11,药材与丹炉!$B:$D,3,0),0),0)+IFERROR(IF(AND($N11>0,$N11<>""),VLOOKUP($M11,药材与丹炉!$B:$D,3,0),0),0)+IFERROR(IF(AND($S11>0,$S11<>""),VLOOKUP($R11,药材与丹炉!$B:$D,3,0),0),0)+IFERROR(IF(AND($W11>0,$W11<>""),VLOOKUP($V11,药材与丹炉!$B:$D,3,0),0),0)<0,2,0)) -> 0 | AA11: =IFERROR($Y11/VLOOKUP($Z11,药材与丹炉!$B:$H,COLUMN(药材与丹炉!$H11)-1,0),"") | AB11: 普通丹炉 | AC11: =IFERROR(IF($B11-VLOOKUP($AB11,药材与丹炉!$N:$P,2,0)<0,IF($AO$1="是",0,1),IF($B11-VLOOKUP($AB11,药材与丹炉!$N:$P,2,0)=0,2,IF($B11-VLOOKUP($AB11,药材与丹炉!$N:$P,2,0)=1,40,IF($B11-VLOOKUP($AB11,药材与丹炉!$N:$P,2,0)=2,80,"爆炸")))),"") -> 2 | AD11: =IFERROR($J11+IFERROR(IF($N11="",0,$N11),0)+IFERROR(IF($S11="",0,$S11),0)+IFERROR(IF($W11="",0,$W11),0)+IFERROR(IF($AA11="",0,$AA11),0),"") -> 2 | AE11: =IFERROR($J11*VLOOKUP($I11,药材与丹炉!$B:$K,10,0),0)+IFERROR($N11*VLOOKUP($M11,药材与丹炉!$B:$K,10,0),0)+IFERROR($S11*VLOOKUP($R11,药材与丹炉!$B:$K,10,0),0)+IFERROR($W11*VLOOKUP($V11,药材与丹炉!$B:$K,10,0),0)+IFERROR($AA11*VLOOKUP($Z11,药材与丹炉!$B:$K,10,0),0)+IFERROR($AC11*VLOOKUP($AB11,药材与丹炉!$N:$P,3,0)/100,0) -> 30 | AF11: 1 | AG11: =$AF11-$AE11 -> -29 | AH11: =$AF11*$AM$1*$AM$21 -> 2 | AI11: =$AH11-$AE11 -> -28 | AJ11: =IFERROR(IF($Y11/VLOOKUP($Y11,药材与丹炉!$T:$U,2,0)<=(VLOOKUP($AB11,药材与丹炉!$N:$O,2,0)+8)-($J11+IFERROR(IF($N11="",0,$N11),0)+IFERROR(IF($S11="",0,$S11),0)+IFERROR(IF($W11="",0,$W11),0)),1,2),1) -> 1 | AK11: =OR(NOT(IFERROR(OR($L11="",AND($L11<>"",$L11>0,VLOOKUP($AB11,药材与丹炉!$N:$O,2,0)=6)),0)),AND($L11<>"",$L11>0,OR(VLOOKUP($AB11,药材与丹炉!$N:$Q,4,0)-2<$N11,$N11="")),AND($U11<>"",$U11>0,OR(VLOOKUP($AB11,药材与丹炉!$N:$Q,4,0)-3<$W11,$W11="")),NOT(OR(AND($Q11<>"",$S11<>"",VLOOKUP($AB11,药材与丹炉!$N:$Q,4,0)-3>=$S11),$P11="")),NOT(OR(AND($H11<>"",$J11<>"",VLOOKUP($AB11,药材与丹炉!$N:$Q,4,0)-1>=$J11),$G11="")),NOT(OR($U11="",AND($U11<>"",$U11>0))),NOT(OR($Y11="",IF($Z11<>"",IFERROR(IF(VLOOKUP($Z11,药材与丹炉!$B:$D,3,0)=-1,$X11=1,IF(VLOOKUP($Z11,药材与丹炉!$B:$D,3,0)=1,$X11=2,$X11=0)),0),0))),$AC11="爆炸",(VLOOKUP($AB11,药材与丹炉!$N:$O,2,0)+8)<$AD11) -> FALSE | AL11: 0.95 | AM11: 在坊市从不感兴趣的NPC收购该丹药【坊市95折】
A12: 5101 | B12: 2 | C12: 培元丹 | D12: 999 | E12: 生命值+170/丹毒+1 | F12: 6 | G12: 活血 | H12: 6 | I12: 银月花 | J12: =IFERROR(CEILING($H12/VLOOKUP($I12,药材与丹炉!$B:$H,COLUMN(药材与丹炉!$H12)-1,0),1),"") -> 6 | K12: 活血 | L12: =IFERROR(IF($F12-$H12=0,"",$F12-$H12),"") | N12: =IFERROR(CEILING($L12/VLOOKUP($M12,药材与丹炉!$B:$H,COLUMN(药材与丹炉!$H12)-1,0),1),"") | O12: 3 | P12: 固元 | Q12: 3 | R12: 何首乌 | S12: =IFERROR(CEILING($Q12/VLOOKUP($R12,药材与丹炉!$B:$H,COLUMN(药材与丹炉!$H12)-1,0),1),"") -> 1 | T12: =P12 -> 固元 | U12: =IFERROR(IF($O12-$Q12=0,"",$O12-$Q12),"") | W12: =IFERROR(CEILING($U12/VLOOKUP($V12,药材与丹炉!$B:$H,COLUMN(药材与丹炉!$H12)-1,0),1),"") | X12: =IF(IFERROR(IF(AND($J12>0,$J12<>""),VLOOKUP($I12,药材与丹炉!$B:$D,3,0),0),0)+IFERROR(IF(AND($N12>0,$N12<>""),VLOOKUP($M12,药材与丹炉!$B:$D,3,0),0),0)+IFERROR(IF(AND($S12>0,$S12<>""),VLOOKUP($R12,药材与丹炉!$B:$D,3,0),0),0)+IFERROR(IF(AND($W12>0,$W12<>""),VLOOKUP($V12,药材与丹炉!$B:$D,3,0),0),0)>0,1,IF(IFERROR(IF(AND($J12>0,$J12<>""),VLOOKUP($I12,药材与丹炉!$B:$D,3,0),0),0)+IFERROR(IF(AND($N12>0,$N12<>""),VLOOKUP($M12,药材与丹炉!$B:$D,3,0),0),0)+IFERROR(IF(AND($S12>0,$S12<>""),VLOOKUP($R12,药材与丹炉!$B:$D,3,0),0),0)+IFERROR(IF(AND($W12>0,$W12<>""),VLOOKUP($V12,药材与丹炉!$B:$D,3,0),0),0)<0,2,0)) -> 0 | Y12: 3 | Z12: 恒心草 | AA12: =IFERROR($Y12/VLOOKUP($Z12,药材与丹炉!$B:$H,COLUMN(药材与丹炉!$H12)-1,0),"") -> 3 | AB12: 陨铁炉 | AC12: =IFERROR(IF($B12-VLOOKUP($AB12,药材与丹炉!$N:$P,2,0)<0,IF($AO$1="是",0,1),IF($B12-VLOOKUP($AB12,药材与丹炉!$N:$P,2,0)=0,2,IF($B12-VLOOKUP($AB12,药材与丹炉!$N:$P,2,0)=1,40,IF($B12-VLOOKUP($AB12,药材与丹炉!$N:$P,2,0)=2,80,"爆炸")))),"") -> 2 | AD12: =IFERROR($J12+IFERROR(IF($N12="",0,$N12),0)+IFERROR(IF($S12="",0,$S12),0)+IFERROR(IF($W12="",0,$W12),0)+IFERROR(IF($AA12="",0,$AA12),0),"") -> 10 | AE12: =IFERROR($J12*VLOOKUP($I12,药材与丹炉!$B:$K,10,0),0)+IFERROR($N12*VLOOKUP($M12,药材与丹炉!$B:$K,10,0),0)+IFERROR($S12*VLOOKUP($R12,药材与丹炉!$B:$K,10,0),0)+IFERROR($W12*VLOOKUP($V12,药材与丹炉!$B:$K,10,0),0)+IFERROR($AA12*VLOOKUP($Z12,药材与丹炉!$B:$K,10,0),0)+IFERROR($AC12*VLOOKUP($AB12,药材与丹炉!$N:$P,3,0)/100,0) -> 141 | AF12: 206 | AG12: =$AF12-$AE12 -> 65 | AH12: =$AF12*$AM$1*$AM$21 -> 412 | AI12: =$AH12-$AE12 -> 271 | AJ12: =IFERROR(IF($Y12/VLOOKUP($Y12,药材与丹炉!$T:$U,2,0)<=(VLOOKUP($AB12,药材与丹炉!$N:$O,2,0)+8)-($J12+IFERROR(IF($N12="",0,$N12),0)+IFERROR(IF($S12="",0,$S12),0)+IFERROR(IF($W12="",0,$W12),0)),1,2),1) -> 1 | AK12: =OR(NOT(IFERROR(OR($L12="",AND($L12<>"",$L12>0,VLOOKUP($AB12,药材与丹炉!$N:$O,2,0)=6)),0)),AND($L12<>"",$L12>0,OR(VLOOKUP($AB12,药材与丹炉!$N:$Q,4,0)-2<$N12,$N12="")),AND($U12<>"",$U12>0,OR(VLOOKUP($AB12,药材与丹炉!$N:$Q,4,0)-3<$W12,$W12="")),NOT(OR(AND($Q12<>"",$S12<>"",VLOOKUP($AB12,药材与丹炉!$N:$Q,4,0)-3>=$S12),$P12="")),NOT(OR(AND($H12<>"",$J12<>"",VLOOKUP($AB12,药材与丹炉!$N:$Q,4,0)-1>=$J12),$G12="")),NOT(OR($U12="",AND($U12<>"",$U12>0))),NOT(OR($Y12="",IF($Z12<>"",IFERROR(IF(VLOOKUP($Z12,药材与丹炉!$B:$D,3,0)=-1,$X12=1,IF(VLOOKUP($Z12,药材与丹炉!$B:$D,3,0)=1,$X12=2,$X12=0)),0),0))),$AC12="爆炸",(VLOOKUP($AB12,药材与丹炉!$N:$O,2,0)+8)<$AD12) -> FALSE | AL12: 0.975 | AM12: 在坊市将物品卖给感兴趣NPC【坊市95折】
A13: 5102 | B13: 2 | C13: 养气丹 | D13: 100 | E13: 修为+553 | F13: 9 | G13: 生息 | H13: 9 | I13: 风灵花 | J13: =IFERROR(CEILING($H13/VLOOKUP($I13,药材与丹炉!$B:$H,COLUMN(药材与丹炉!$H13)-1,0),1),"") -> 3 | K13: 生息 | L13: =IFERROR(IF($F13-$H13=0,"",$F13-$H13),"") | N13: =IFERROR(CEILING($L13/VLOOKUP($M13,药材与丹炉!$B:$H,COLUMN(药材与丹炉!$H13)-1,0),1),"") | O13: 21 | P13: 养气 | Q13: 21 | R13: 轻灵草 | S13: =IFERROR(CEILING($Q13/VLOOKUP($R13,药材与丹炉!$B:$H,COLUMN(药材与丹炉!$H13)-1,0),1),"") -> 7 | T13: =P13 -> 养气 | U13: =IFERROR(IF($O13-$Q13=0,"",$O13-$Q13),"") | W13: =IFERROR(CEILING($U13/VLOOKUP($V13,药材与丹炉!$B:$H,COLUMN(药材与丹炉!$H13)-1,0),1),"") | X13: =IF(IFERROR(IF(AND($J13>0,$J13<>""),VLOOKUP($I13,药材与丹炉!$B:$D,3,0),0),0)+IFERROR(IF(AND($N13>0,$N13<>""),VLOOKUP($M13,药材与丹炉!$B:$D,3,0),0),0)+IFERROR(IF(AND($S13>0,$S13<>""),VLOOKUP($R13,药材与丹炉!$B:$D,3,0),0),0)+IFERROR(IF(AND($W13>0,$W13<>""),VLOOKUP($V13,药材与丹炉!$B:$D,3,0),0),0)>0,1,IF(IFERROR(IF(AND($J13>0,$J13<>""),VLOOKUP($I13,药材与丹炉!$B:$D,3,0),0),0)+IFERROR(IF(AND($N13>0,$N13<>""),VLOOKUP($M13,药材与丹炉!$B:$D,3,0),0),0)+IFERROR(IF(AND($S13>0,$S13<>""),VLOOKUP($R13,药材与丹炉!$B:$D,3,0),0),0)+IFERROR(IF(AND($W13>0,$W13<>""),VLOOKUP($V13,药材与丹炉!$B:$D,3,0),0),0)<0,2,0)) -> 2 | Y13: 3 | Z13: 地黄参 | AA13: =IFERROR($Y13/VLOOKUP($Z13,药材与丹炉!$B:$H,COLUMN(药材与丹炉!$H13)-1,0),"") -> 1 | AB13: 雕花紫铜炉 | AC13: =IFERROR(IF($B13-VLOOKUP($AB13,药材与丹炉!$N:$P,2,0)<0,IF($AO$1="是",0,1),IF($B13-VLOOKUP($AB13,药材与丹炉!$N:$P,2,0)=0,2,IF($B13-VLOOKUP($AB13,药材与丹炉!$N:$P,2,0)=1,40,IF($B13-VLOOKUP($AB13,药材与丹炉!$N:$P,2,0)=2,80,"爆炸")))),"") -> 1 | AD13: =IFERROR($J13+IFERROR(IF($N13="",0,$N13),0)+IFERROR(IF($S13="",0,$S13),0)+IFERROR(IF($W13="",0,$W13),0)+IFERROR(IF($AA13="",0,$AA13),0),"") -> 11 | AE13: =IFERROR($J13*VLOOKUP($I13,药材与丹炉!$B:$K,10,0),0)+IFERROR($N13*VLOOKUP($M13,药材与丹炉!$B:$K,10,0),0)+IFERROR($S13*VLOOKUP($R13,药材与丹炉!$B:$K,10,0),0)+IFERROR($W13*VLOOKUP($V13,药材与丹炉!$B:$K,10,0),0)+IFERROR($AA13*VLOOKUP($Z13,药材与丹炉!$B:$K,10,0),0)+IFERROR($AC13*VLOOKUP($AB13,药材与丹炉!$N:$P,3,0)/100,0) -> 436 | AF13: 608 | AG13: =$AF13-$AE13 -> 172 | AH13: =$AF13*$AM$1*$AM$21 -> 1216 | AI13: =$AH13-$AE13 -> 780 | AJ13: =IFERROR(IF($Y13/VLOOKUP($Y13,药材与丹炉!$T:$U,2,0)<=(VLOOKUP($AB13,药材与丹炉!$N:$O,2,0)+8)-($J13+IFERROR(IF($N13="",0,$N13),0)+IFERROR(IF($S13="",0,$S13),0)+IFERROR(IF($W13="",0,$W13),0)),1,2),1) -> 2 | AK13: =OR(NOT(IFERROR(OR($L13="",AND($L13<>"",$L13>0,VLOOKUP($AB13,药材与丹炉!$N:$O,2,0)=6)),0)),AND($L13<>"",$L13>0,OR(VLOOKUP($AB13,药材与丹炉!$N:$Q,4,0)-2<$N13,$N13="")),AND($U13<>"",$U13>0,OR(VLOOKUP($AB13,药材与丹炉!$N:$Q,4,0)-3<$W13,$W13="")),NOT(OR(AND($Q13<>"",$S13<>"",VLOOKUP($AB13,药材与丹炉!$N:$Q,4,0)-3>=$S13),$P13="")),NOT(OR(AND($H13<>"",$J13<>"",VLOOKUP($AB13,药材与丹炉!$N:$Q,4,0)-1>=$J13),$G13="")),NOT(OR($U13="",AND($U13<>"",$U13>0))),NOT(OR($Y13="",IF($Z13<>"",IFERROR(IF(VLOOKUP($Z13,药材与丹炉!$B:$D,3,0)=-1,$X13=1,IF(VLOOKUP($Z13,药材与丹炉!$B:$D,3,0)=1,$X13=2,$X13=0)),0),0))),$AC13="爆炸",(VLOOKUP($AB13,药材与丹炉!$N:$O,2,0)+8)<$AD13) -> FALSE | AL13: 1 | AM13: 在非坊市地区将物品卖给感兴趣的NPC或者从不感兴趣NPC收购
A14: 5103 | B14: 2 | C14: 疾行丹 | D14: 100 | E14: 本场战斗中遁速+5/丹毒+3 | F14: 3 | G14: 振气 | H14: 3 | I14: 宁心草 | J14: =IFERROR(CEILING($H14/VLOOKUP($I14,药材与丹炉!$B:$H,COLUMN(药材与丹炉!$H14)-1,0),1),"") -> 3 | K14: 振气 | L14: =IFERROR(IF($F14-$H14=0,"",$F14-$H14),"") | N14: =IFERROR(CEILING($L14/VLOOKUP($M14,药材与丹炉!$B:$H,COLUMN(药材与丹炉!$H14)-1,0),1),"") | O14: 3 | P14: 神行 | Q14: 3 | R14: 夏枯草 | S14: =IFERROR(CEILING($Q14/VLOOKUP($R14,药材与丹炉!$B:$H,COLUMN(药材与丹炉!$H14)-1,0),1),"") -> 1 | T14: =P14 -> 神行 | U14: =IFERROR(IF($O14-$Q14=0,"",$O14-$Q14),"") | W14: =IFERROR(CEILING($U14/VLOOKUP($V14,药材与丹炉!$B:$H,COLUMN(药材与丹炉!$H14)-1,0),1),"") | X14: =IF(IFERROR(IF(AND($J14>0,$J14<>""),VLOOKUP($I14,药材与丹炉!$B:$D,3,0),0),0)+IFERROR(IF(AND($N14>0,$N14<>""),VLOOKUP($M14,药材与丹炉!$B:$D,3,0),0),0)+IFERROR(IF(AND($S14>0,$S14<>""),VLOOKUP($R14,药材与丹炉!$B:$D,3,0),0),0)+IFERROR(IF(AND($W14>0,$W14<>""),VLOOKUP($V14,药材与丹炉!$B:$D,3,0),0),0)>0,1,IF(IFERROR(IF(AND($J14>0,$J14<>""),VLOOKUP($I14,药材与丹炉!$B:$D,3,0),0),0)+IFERROR(IF(AND($N14>0,$N14<>""),VLOOKUP($M14,药材与丹炉!$B:$D,3,0),0),0)+IFERROR(IF(AND($S14>0,$S14<>""),VLOOKUP($R14,药材与丹炉!$B:$D,3,0),0),0)+IFERROR(IF(AND($W14>0,$W14<>""),VLOOKUP($V14,药材与丹炉!$B:$D,3,0),0),0)<0,2,0)) -> 0 | Y14: 1 | Z14: 恒心草 | AA14: =IFERROR($Y14/VLOOKUP($Z14,药材与丹炉!$B:$H,COLUMN(药材与丹炉!$H14)-1,0),"") -> 1 | AB14: 陨铁炉 | AC14: =IFERROR(IF($B14-VLOOKUP($AB14,药材与丹炉!$N:$P,2,0)<0,IF($AO$1="是",0,1),IF($B14-VLOOKUP($AB14,药材与丹炉!$N:$P,2,0)=0,2,IF($B14-VLOOKUP($AB14,药材与丹炉!$N:$P,2,0)=1,40,IF($B14-VLOOKUP($AB14,药材与丹炉!$N:$P,2,0)=2,80,"爆炸")))),"") -> 2 | AD14: =IFERROR($J14+IFERROR(IF($N14="",0,$N14),0)+IFERROR(IF($S14="",0,$S14),0)+IFERROR(IF($W14="",0,$W14),0)+IFERROR(IF($AA14="",0,$AA14),0),"") -> 5 | AE14: =IFERROR($J14*VLOOKUP($I14,药材与丹炉!$B:$K,10,0),0)+IFERROR($N14*VLOOKUP($M14,药材与丹炉!$B:$K,10,0),0)+IFERROR($S14*VLOOKUP($R14,药材与丹炉!$B:$K,10,0),0)+IFERROR($W14*VLOOKUP($V14,药材与丹炉!$B:$K,10,0),0)+IFERROR($AA14*VLOOKUP($Z14,药材与丹炉!$B:$K,10,0),0)+IFERROR($AC14*VLOOKUP($AB14,药材与丹炉!$N:$P,3,0)/100,0) -> 96 | AF14: 143 | AG14: =$AF14-$AE14 -> 47 | AH14: =$AF14*$AM$1*$AM$21 -> 286 | AI14: =$AH14-$AE14 -> 190 | AJ14: =IFERROR(IF($Y14/VLOOKUP($Y14,药材与丹炉!$T:$U,2,0)<=(VLOOKUP($AB14,药材与丹炉!$N:$O,2,0)+8)-($J14+IFERROR(IF($N14="",0,$N14),0)+IFERROR(IF($S14="",0,$S14),0)+IFERROR(IF($W14="",0,$W14),0)),1,2),1) -> 1 | AK14: =OR(NOT(IFERROR(OR($L14="",AND($L14<>"",$L14>0,VLOOKUP($AB14,药材与丹炉!$N:$O,2,0)=6)),0)),AND($L14<>"",$L14>0,OR(VLOOKUP($AB14,药材与丹炉!$N:$Q,4,0)-2<$N14,$N14="")),AND($U14<>"",$U14>0,OR(VLOOKUP($AB14,药材与丹炉!$N:$Q,4,0)-3<$W14,$W14="")),NOT(OR(AND($Q14<>"",$S14<>"",VLOOKUP($AB14,药材与丹炉!$N:$Q,4,0)-3>=$S14),$P14="")),NOT(OR(AND($H14<>"",$J14<>"",VLOOKUP($AB14,药材与丹炉!$N:$Q,4,0)-1>=$J14),$G14="")),NOT(OR($U14="",AND($U14<>"",$U14>0))),NOT(OR($Y14="",IF($Z14<>"",IFERROR(IF(VLOOKUP($Z14,药材与丹炉!$B:$D,3,0)=-1,$X14=1,IF(VLOOKUP($Z14,药材与丹炉!$B:$D,3,0)=1,$X14=2,$X14=0)),0),0))),$AC14="爆炸",(VLOOKUP($AB14,药材与丹炉!$N:$O,2,0)+8)<$AD14) -> FALSE | AL14: 1.5 | AM14: 在灵药堂的购买丹药的价格
A15: 5104 | B15: 2 | C15: 黄龙丹 | D15: 999 | E15: 生命值+320/丹毒+2 | F15: 3 | G15: 活血 | H15: 3 | I15: 银月花 | J15: =IFERROR(CEILING($H15/VLOOKUP($I15,药材与丹炉!$B:$H,COLUMN(药材与丹炉!$H15)-1,0),1),"") -> 3 | K15: 活血 | L15: =IFERROR(IF($F15-$H15=0,"",$F15-$H15),"") | N15: =IFERROR(CEILING($L15/VLOOKUP($M15,药材与丹炉!$B:$H,COLUMN(药材与丹炉!$H15)-1,0),1),"") | O15: 18 | P15: 培元 | Q15: 18 | R15: 红绫草 | S15: =IFERROR(CEILING($Q15/VLOOKUP($R15,药材与丹炉!$B:$H,COLUMN(药材与丹炉!$H15)-1,0),1),"") -> 6 | T15: =P15 -> 培元 | U15: =IFERROR(IF($O15-$Q15=0,"",$O15-$Q15),"") | W15: =IFERROR(CEILING($U15/VLOOKUP($V15,药材与丹炉!$B:$H,COLUMN(药材与丹炉!$H15)-1,0),1),"") | X15: =IF(IFERROR(IF(AND($J15>0,$J15<>""),VLOOKUP($I15,药材与丹炉!$B:$D,3,0),0),0)+IFERROR(IF(AND($N15>0,$N15<>""),VLOOKUP($M15,药材与丹炉!$B:$D,3,0),0),0)+IFERROR(IF(AND($S15>0,$S15<>""),VLOOKUP($R15,药材与丹炉!$B:$D,3,0),0),0)+IFERROR(IF(AND($W15>0,$W15<>""),VLOOKUP($V15,药材与丹炉!$B:$D,3,0),0),0)>0,1,IF(IFERROR(IF(AND($J15>0,$J15<>""),VLOOKUP($I15,药材与丹炉!$B:$D,3,0),0),0)+IFERROR(IF(AND($N15>0,$N15<>""),VLOOKUP($M15,药材与丹炉!$B:$D,3,0),0),0)+IFERROR(IF(AND($S15>0,$S15<>""),VLOOKUP($R15,药材与丹炉!$B:$D,3,0),0),0)+IFERROR(IF(AND($W15>0,$W15<>""),VLOOKUP($V15,药材与丹炉!$B:$D,3,0),0),0)<0,2,0)) -> 2 | Y15: 3 | Z15: 地黄参 | AA15: =IFERROR($Y15/VLOOKUP($Z15,药材与丹炉!$B:$H,COLUMN(药材与丹炉!$H15)-1,0),"") -> 1 | AB15: 陨铁炉 | AC15: =IFERROR(IF($B15-VLOOKUP($AB15,药材与丹炉!$N:$P,2,0)<0,IF($AO$1="是",0,1),IF($B15-VLOOKUP($AB15,药材与丹炉!$N:$P,2,0)=0,2,IF($B15-VLOOKUP($AB15,药材与丹炉!$N:$P,2,0)=1,40,IF($B15-VLOOKUP($AB15,药材与丹炉!$N:$P,2,0)=2,80,"爆炸")))),"") -> 2 | AD15: =IFERROR($J15+IFERROR(IF($N15="",0,$N15),0)+IFERROR(IF($S15="",0,$S15),0)+IFERROR(IF($W15="",0,$W15),0)+IFERROR(IF($AA15="",0,$AA15),0),"") -> 10 | AE15: =IFERROR($J15*VLOOKUP($I15,药材与丹炉!$B:$K,10,0),0)+IFERROR($N15*VLOOKUP($M15,药材与丹炉!$B:$K,10,0),0)+IFERROR($S15*VLOOKUP($R15,药材与丹炉!$B:$K,10,0),0)+IFERROR($W15*VLOOKUP($V15,药材与丹炉!$B:$K,10,0),0)+IFERROR($AA15*VLOOKUP($Z15,药材与丹炉!$B:$K,10,0),0)+IFERROR($AC15*VLOOKUP($AB15,药材与丹炉!$N:$P,3,0)/100,0) -> 303 | AF15: 356 | AG15: =$AF15-$AE15 -> 53 | AH15: =$AF15*$AM$1*$AM$21 -> 712 | AI15: =$AH15-$AE15 -> 409 | AJ15: =IFERROR(IF($Y15/VLOOKUP($Y15,药材与丹炉!$T:$U,2,0)<=(VLOOKUP($AB15,药材与丹炉!$N:$O,2,0)+8)-($J15+IFERROR(IF($N15="",0,$N15),0)+IFERROR(IF($S15="",0,$S15),0)+IFERROR(IF($W15="",0,$W15),0)),1,2),1) -> 2 | AK15: =OR(NOT(IFERROR(OR($L15="",AND($L15<>"",$L15>0,VLOOKUP($AB15,药材与丹炉!$N:$O,2,0)=6)),0)),AND($L15<>"",$L15>0,OR(VLOOKUP($AB15,药材与丹炉!$N:$Q,4,0)-2<$N15,$N15="")),AND($U15<>"",$U15>0,OR(VLOOKUP($AB15,药材与丹炉!$N:$Q,4,0)-3<$W15,$W15="")),NOT(OR(AND($Q15<>"",$S15<>"",VLOOKUP($AB15,药材与丹炉!$N:$Q,4,0)-3>=$S15),$P15="")),NOT(OR(AND($H15<>"",$J15<>"",VLOOKUP($AB15,药材与丹炉!$N:$Q,4,0)-1>=$J15),$G15="")),NOT(OR($U15="",AND($U15<>"",$U15>0))),NOT(OR($Y15="",IF($Z15<>"",IFERROR(IF(VLOOKUP($Z15,药材与丹炉!$B:$D,3,0)=-1,$X15=1,IF(VLOOKUP($Z15,药材与丹炉!$B:$D,3,0)=1,$X15=2,$X15=0)),0),0))),$AC15="爆炸",(VLOOKUP($AB15,药材与丹炉!$N:$O,2,0)+8)<$AD15) -> FALSE | AL15: 2 | AM15: 领悟丹圣后出双倍丹，且在非坊市地区将物品卖给感兴趣NPC的双倍价
